Workbook

Sheet Tổng hợp
A1: BẢNG TỔNG HỢP KIỂM KÊ SIM/CỤC WIFI - CẬP NHẬT 24/09/2026
B3: kế toán check in ra ký | C3: kế toán check in ra ký | E3: chị thơm kt và ký | F3: kế toán check in ra ký | G3: chị thơm kt và ký | H3: kế toán check in ra ký | I3: chị thơm kt và ký | L3: kế toán check in ra ký | M3: kho ký | N3: kế toán check in ra ký | O3: kế toán check in ra ký | R3: kế toán check in ra ký | S3: kế toán check in ra ký | T3: kế toán check in ra ký | U3: kế toán check in ra ký | V3: kế toán check in ra ký | W3: kế toán check in ra ký
B4: Tổng nhập (file nhập) | C4: Trả lại Luna | D4: Nhập thực giữ | E4: Khách lẻ + CTV (đang dùng) | F4: Đại lý (đang dùng) | G4: Dùng chờ cố định | H4: Chờ kích hoạt / Chờ hủy | I4: Cần thu hồi thực tế (file PM) | J4: Tổng | K4: check lệch lần 1 | L4: Tồn kho Việt Nam | M4: Kiểm kho Takanoba 24/09 | N4: Tồn kho Ibaraki (còn trong kho) | O4: Ibaraki đã bán chưa nhập PM | P4: Tổng | Q4: chênh lệch lần 2 | R4: Sim trả lại nhà mạng | S4: Sim đã hủy | T4: Đối tác đang dùng (sim / cục) | U4: Xuất đại lý ( đợi kích hoạt ) | V4: mất không có dữ liệu | W4: Hỏng / trả/ làm hợp quy nhà cung cấp | X4: tổng | Y4: lệch
B5: (1) | C5: (2) | D5: (3)=(1)-(2) | E5: (4) | F5: (5) | G5: (6) | H5: (7) | I5: (8) | J5: (4)+..+(8) | K5: (3) − Tổng | L5: (9) | M5: (10) | N5: (11) | O5: (12) | P5: (9)+..+(12) | Q5: lệch trước − Tổng | R5: (13) | S5: (14) | T5: (15) | U5: (16) | V5: (17) | W5: (18) | X5: (13)+..+(18) | Y5: lệch trước − Tổng
A6: U20 | B6: =COUNTIF('01_Nhap_hang'!$A:$A,$A6) -> 5000 | C6: =COUNTIF('02_Tra_Luna'!$A:$A,$A6) -> 2000 | D6: =B6-C6 -> 3000 | E6: =COUNTIF('04_Khach_le_CTV'!$A:$A,$A6) -> 848 | F6: =COUNTIF('05_Dai_ly'!$A:$A,$A6) -> 225 | G6: =COUNTIF('06_Cho_co_dinh'!$A:$A,$A6) -> 152 | H6: =COUNTIF('07_Cho_kich_hoat'!$A:$A,$A6) -> 6 | I6: =COUNTIF('08_Can_thu_hoi'!$A:$A,$A6) -> 371 | J6: =SUM(E6:I6) -> 1602 | K6: =D6-J6 -> 1398 | L6: =COUNTIF('09_Kho_Viet_Nam'!$A:$A,$A6) -> 583 | M6: =COUNTIFS('10_Kho_Takanoba'!$A:$A,$A6,'10_Kho_Takanoba'!$E:$E,"") -> 252 | N6: =COUNTIFS('11_Kho_Ibaraki'!$A:$A,$A6,'11_Kho_Ibaraki'!$G:$G,"") -> 32 | O6: =COUNTIFS('12_Ibaraki_da_ban'!$A:$A,$A6,'12_Ibaraki_da_ban'!$E:$E,"") -> 375 | P6: =SUM(L6:O6) -> 1242 | Q6: =K6-P6 -> 156 | R6: =COUNTIFS('13_Sim_tra_nha_mang'!$A:$A,$A6,'13_Sim_tra_nha_mang'!$F:$F,"") -> 0 | S6: =COUNTIFS('14_Sim_da_huy'!$A:$A,$A6,'14_Sim_da_huy'!$F:$F,"") -> 0 | T6: =COUNTIFS('15_Doi_tac_de_lai'!$A:$A,$A6,'15_Doi_tac_de_lai'!$E:$E,"") -> 5 | U6: =COUNTIFS('16_Xuat_dai_ly'!$A:$A,$A6,'16_Xuat_dai_ly'!$H:$H,"") -> 133 | V6: =COUNTIFS('17_Khong_thay_nhap_kho'!$A:$A,$A6,'17_Khong_thay_nhap_kho'!$E:$E,"") -> 9 | W6: =COUNTIFS('18_Hong_tra_NCC'!$A:$A,$A6,'18_Hong_tra_NCC'!$E:$E,"") -> 9 | X6: =SUM(R6:W6) -> 156 | Y6: =Q6-X6 -> 0
A7: MR1 | B7: =COUNTIF('01_Nhap_hang'!$A:$A,$A7) -> 660 | C7: =COUNTIF('02_Tra_Luna'!$A:$A,$A7) -> 0 | D7: =B7-C7 -> 660 | E7: =COUNTIF('04_Khach_le_CTV'!$A:$A,$A7) -> 163 | F7: =COUNTIF('05_Dai_ly'!$A:$A,$A7) -> 0 | G7: =COUNTIF('06_Cho_co_dinh'!$A:$A,$A7) -> 0 | H7: =COUNTIF('07_Cho_kich_hoat'!$A:$A,$A7) -> 8 | I7: =COUNTIF('08_Can_thu_hoi'!$A:$A,$A7) -> 27 | J7: =SUM(E7:I7) -> 198 | K7: =D7-J7 -> 462 | L7: =COUNTIF('09_Kho_Viet_Nam'!$A:$A,$A7) -> 0 | M7: =COUNTIFS('10_Kho_Takanoba'!$A:$A,$A7,'10_Kho_Takanoba'!$E:$E,"") -> 460 | N7: =COUNTIFS('11_Kho_Ibaraki'!$A:$A,$A7,'11_Kho_Ibaraki'!$G:$G,"") -> 0 | O7: =COUNTIFS('12_Ibaraki_da_ban'!$A:$A,$A7,'12_Ibaraki_da_ban'!$E:$E,"") -> 0 | P7: =SUM(L7:O7) -> 460 | Q7: =K7-P7 -> 2 | R7: =COUNTIFS('13_Sim_tra_nha_mang'!$A:$A,$A7,'13_Sim_tra_nha_mang'!$F:$F,"") -> 0 | S7: =COUNTIFS('14_Sim_da_huy'!$A:$A,$A7,'14_Sim_da_huy'!$F:$F,"") -> 0 | T7: =COUNTIFS('15_Doi_tac_de_lai'!$A:$A,$A7,'15_Doi_tac_de_lai'!$E:$E,"") -> 0 | U7: =COUNTIFS('16_Xuat_dai_ly'!$A:$A,$A7,'16_Xuat_dai_ly'!$H:$H,"") -> 0 | V7: =COUNTIFS('17_Khong_thay_nhap_kho'!$A:$A,$A7,'17_Khong_thay_nhap_kho'!$E:$E,"") -> 2 | W7: =COUNTIFS('18_Hong_tra_NCC'!$A:$A,$A7,'18_Hong_tra_NCC'!$E:$E,"") -> 0 | X7: =SUM(R7:W7) -> 2 | Y7: =Q7-X7 -> 0
A8: WIMAX | B8: =COUNTIF('01_Nhap_hang'!$A:$A,$A8) -> 137 | C8: =COUNTIF('02_Tra_Luna'!$A:$A,$A8) -> 0 | D8: =B8-C8 -> 137 | E8: =COUNTIF('04_Khach_le_CTV'!$A:$A,$A8) -> 104 | F8: =COUNTIF('05_Dai_ly'!$A:$A,$A8) -> 0 | G8: =COUNTIF('06_Cho_co_dinh'!$A:$A,$A8) -> 0 | H8: =COUNTIF('07_Cho_kich_hoat'!$A:$A,$A8) -> 0 | I8: =COUNTIF('08_Can_thu_hoi'!$A:$A,$A8) -> 23 | J8: =SUM(E8:I8) -> 127 | K8: =D8-J8 -> 10 | L8: =COUNTIF('09_Kho_Viet_Nam'!$A:$A,$A8) -> 0 | M8: =COUNTIFS('10_Kho_Takanoba'!$A:$A,$A8,'10_Kho_Takanoba'!$E:$E,"") -> 7 | N8: =COUNTIFS('11_Kho_Ibaraki'!$A:$A,$A8,'11_Kho_Ibaraki'!$G:$G,"") -> 0 | O8: =COUNTIFS('12_Ibaraki_da_ban'!$A:$A,$A8,'12_Ibaraki_da_ban'!$E:$E,"") -> 0 | P8: =SUM(L8:O8) -> 7 | Q8: =K8-P8 -> 3 | R8: =COUNTIFS('13_Sim_tra_nha_mang'!$A:$A,$A8,'13_Sim_tra_nha_mang'!$F:$F,"") -> 0 | S8: =COUNTIFS('14_Sim_da_huy'!$A:$A,$A8,'14_Sim_da_huy'!$F:$F,"") -> 0 | T8: =COUNTIFS('15_Doi_tac_de_lai'!$A:$A,$A8,'15_Doi_tac_de_lai'!$E:$E,"") -> 2 | U8: =COUNTIFS('16_Xuat_dai_ly'!$A:$A,$A8,'16_Xuat_dai_ly'!$H:$H,"") -> 0 | V8: =COUNTIFS('17_Khong_thay_nhap_kho'!$A:$A,$A8,'17_Khong_thay_nhap_kho'!$E:$E,"") -> 0 | W8: =COUNTIFS('18_Hong_tra_NCC'!$A:$A,$A8,'18_Hong_tra_NCC'!$E:$E,"") -> 1 | X8: =SUM(R8:W8) -> 3 | Y8: =Q8-X8 -> 0
A9: SB 100GB | B9: =COUNTIF('01_Nhap_hang'!$A:$A,$A9) -> 475 | C9: =COUNTIF('02_Tra_Luna'!$A:$A,$A9) -> 0 | D9: =B9-C9 -> 475 | E9: =COUNTIF('04_Khach_le_CTV'!$A:$A,$A9) -> 53 | F9: =COUNTIF('05_Dai_ly'!$A:$A,$A9) -> 25 | G9: =COUNTIF('06_Cho_co_dinh'!$A:$A,$A9) -> 0 | H9: =COUNTIF('07_Cho_kich_hoat'!$A:$A,$A9) -> 0 | I9: =COUNTIF('08_Can_thu_hoi'!$A:$A,$A9) -> 0 | J9: =SUM(E9:I9) -> 78 | K9: =D9-J9 -> 397 | L9: =COUNTIF('09_Kho_Viet_Nam'!$A:$A,$A9) -> 0 | M9: =COUNTIFS('10_Kho_Takanoba'!$A:$A,$A9,'10_Kho_Takanoba'!$E:$E,"") -> 14 | N9: =COUNTIFS('11_Kho_Ibaraki'!$A:$A,$A9,'11_Kho_Ibaraki'!$G:$G,"") -> 0 | O9: =COUNTIFS('12_Ibaraki_da_ban'!$A:$A,$A9,'12_Ibaraki_da_ban'!$E:$E,"") -> 0 | P9: =SUM(L9:O9) -> 14 | Q9: =K9-P9 -> 383 | R9: =COUNTIFS('13_Sim_tra_nha_mang'!$A:$A,$A9,'13_Sim_tra_nha_mang'!$F:$F,"") -> 112 | S9: =COUNTIFS('14_Sim_da_huy'!$A:$A,$A9,'14_Sim_da_huy'!$F:$F,"") -> 270 | T9: =COUNTIFS('15_Doi_tac_de_lai'!$A:$A,$A9,'15_Doi_tac_de_lai'!$E:$E,"") -> 1 | U9: =COUNTIFS('16_Xuat_dai_ly'!$A:$A,$A9,'16_Xuat_dai_ly'!$H:$H,"") -> 0 | V9: =COUNTIFS('17_Khong_thay_nhap_kho'!$A:$A,$A9,'17_Khong_thay_nhap_kho'!$E:$E,"") -> 0 | W9: =COUNTIFS('18_Hong_tra_NCC'!$A:$A,$A9,'18_Hong_tra_NCC'!$E:$E,"") -> 0 | X9: =SUM(R9:W9) -> 383 | Y9: =Q9-X9 -> 0
A10: SB 50GB | B10: =COUNTIF('01_Nhap_hang'!$A:$A,$A10) -> 152 | C10: =COUNTIF('02_Tra_Luna'!$A:$A,$A10) -> 0 | D10: =B10-C10 -> 152 | E10: =COUNTIF('04_Khach_le_CTV'!$A:$A,$A10) -> 24 | F10: =COUNTIF('05_Dai_ly'!$A:$A,$A10) -> 0 | G10: =COUNTIF('06_Cho_co_dinh'!$A:$A,$A10) -> 0 | H10: =COUNTIF('07_Cho_kich_hoat'!$A:$A,$A10) -> 0 | I10: =COUNTIF('08_Can_thu_hoi'!$A:$A,$A10) -> 0 | J10: =SUM(E10:I10) -> 24 | K10: =D10-J10 -> 128 | L10: =COUNTIF('09_Kho_Viet_Nam'!$A:$A,$A10) -> 0 | M10: =COUNTIFS('10_Kho_Takanoba'!$A:$A,$A10,'10_Kho_Takanoba'!$E:$E,"") -> 5 | N10: =COUNTIFS('11_Kho_Ibaraki'!$A:$A,$A10,'11_Kho_Ibaraki'!$G:$G,"") -> 0 | O10: =COUNTIFS('12_Ibaraki_da_ban'!$A:$A,$A10,'12_Ibaraki_da_ban'!$E:$E,"") -> 0 | P10: =SUM(L10:O10) -> 5 | Q10: =K10-P10 -> 123 | R10: =COUNTIFS('13_Sim_tra_nha_mang'!$A:$A,$A10,'13_Sim_tra_nha_mang'!$F:$F,"") -> 20 | S10: =COUNTIFS('14_Sim_da_huy'!$A:$A,$A10,'14_Sim_da_huy'!$F:$F,"") -> 103 | T10: =COUNTIFS('15_Doi_tac_de_lai'!$A:$A,$A10,'15_Doi_tac_de_lai'!$E:$E,"") -> 0 | U10: =COUNTIFS('16_Xuat_dai_ly'!$A:$A,$A10,'16_Xuat_dai_ly'!$H:$H,"") -> 0 | V10: =COUNTIFS('17_Khong_thay_nhap_kho'!$A:$A,$A10,'17_Khong_thay_nhap_kho'!$E:$E,"") -> 0 | W10: =COUNTIFS('18_Hong_tra_NCC'!$A:$A,$A10,'18_Hong_tra_NCC'!$E:$E,"") -> 0 | X10: =SUM(R10:W10) -> 123 | Y10: =Q10-X10 -> 0
A11: Datacall esim | B11: =COUNTIF('01_Nhap_hang'!$A:$A,$A11) -> 96 | C11: =COUNTIF('02_Tra_Luna'!$A:$A,$A11) -> 0 | D11: =B11-C11 -> 96 | E11: =COUNTIF('04_Khach_le_CTV'!$A:$A,$A11) -> 3 | F11: =COUNTIF('05_Dai_ly'!$A:$A,$A11) -> 3 | G11: =COUNTIF('06_Cho_co_dinh'!$A:$A,$A11) -> 0 | H11: =COUNTIF('07_Cho_kich_hoat'!$A:$A,$A11) -> 0 | I11: =COUNTIF('08_Can_thu_hoi'!$A:$A,$A11) -> 0 | J11: =SUM(E11:I11) -> 6 | K11: =D11-J11 -> 90 | L11: =COUNTIF('09_Kho_Viet_Nam'!$A:$A,$A11) -> 0 | M11: =COUNTIFS('10_Kho_Takanoba'!$A:$A,$A11,'10_Kho_Takanoba'!$E:$E,"") -> 0 | N11: =COUNTIFS('11_Kho_Ibaraki'!$A:$A,$A11,'11_Kho_Ibaraki'!$G:$G,"") -> 0 | O11: =COUNTIFS('12_Ibaraki_da_ban'!$A:$A,$A11,'12_Ibaraki_da_ban'!$E:$E,"") -> 0 | P11: =SUM(L11:O11) -> 0 | Q11: =K11-P11 -> 90 | R11: =COUNTIFS('13_Sim_tra_nha_mang'!$A:$A,$A11,'13_Sim_tra_nha_mang'!$F:$F,"") -> 0 | S11: =COUNTIFS('14_Sim_da_huy'!$A:$A,$A11,'14_Sim_da_huy'!$F:$F,"") -> 90 | T11: =COUNTIFS('15_Doi_tac_de_lai'!$A:$A,$A11,'15_Doi_tac_de_lai'!$E:$E,"") -> 0 | U11: =COUNTIFS('16_Xuat_dai_ly'!$A:$A,$A11,'16_Xuat_dai_ly'!$H:$H,"") -> 0 | V11: =COUNTIFS('17_Khong_thay_nhap_kho'!$A:$A,$A11,'17_Khong_thay_nhap_kho'!$E:$E,"") -> 0 | W11: =COUNTIFS('18_Hong_tra_NCC'!$A:$A,$A11,'18_Hong_tra_NCC'!$E:$E,"") -> 0 | X11: =SUM(R11:W11) -> 90 | Y11: =Q11-X11 -> 0
A12: Datacall vật lý | B12: =COUNTIF('01_Nhap_hang'!$A:$A,$A12) -> 332 | C12: =COUNTIF('02_Tra_Luna'!$A:$A,$A12) -> 0 | D12: =B12-C12 -> 332 | E12: =COUNTIF('04_Khach_le_CTV'!$A:$A,$A12) -> 58 | F12: =COUNTIF('05_Dai_ly'!$A:$A,$A12) -> 5 | G12: =COUNTIF('06_Cho_co_dinh'!$A:$A,$A12) -> 0 | H12: =COUNTIF('07_Cho_kich_hoat'!$A:$A,$A12) -> 0 | I12: =COUNTIF('08_Can_thu_hoi'!$A:$A,$A12) -> 0 | J12: =SUM(E12:I12) -> 63 | K12: =D12-J12 -> 269 | L12: =COUNTIF('09_Kho_Viet_Nam'!$A:$A,$A12) -> 0 | M12: =COUNTIFS('10_Kho_Takanoba'!$A:$A,$A12,'10_Kho_Takanoba'!$E:$E,"") -> 8 | N12: =COUNTIFS('11_Kho_Ibaraki'!$A:$A,$A12,'11_Kho_Ibaraki'!$G:$G,"") -> 0 | O12: =COUNTIFS('12_Ibaraki_da_ban'!$A:$A,$A12,'12_Ibaraki_da_ban'!$E:$E,"") -> 0 | P12: =SUM(L12:O12) -> 8 | Q12: =K12-P12 -> 261 | R12: =COUNTIFS('13_Sim_tra_nha_mang'!$A:$A,$A12,'13_Sim_tra_nha_mang'!$F:$F,"") -> 100 | S12: =COUNTIFS('14_Sim_da_huy'!$A:$A,$A12,'14_Sim_da_huy'!$F:$F,"") -> 153 | T12: =COUNTIFS('15_Doi_tac_de_lai'!$A:$A,$A12,'15_Doi_tac_de_lai'!$E:$E,"") -> 8 | U12: =COUNTIFS('16_Xuat_dai_ly'!$A:$A,$A12,'16_Xuat_dai_ly'!$H:$H,"") -> 0 | V12: =COUNTIFS('17_Khong_thay_nhap_kho'!$A:$A,$A12,'17_Khong_thay_nhap_kho'!$E:$E,"") -> 0 | W12: =COUNTIFS('18_Hong_tra_NCC'!$A:$A,$A12,'18_Hong_tra_NCC'!$E:$E,"") -> 0 | X12: =SUM(R12:W12) -> 261 | Y12: =Q12-X12 -> 0
A13: Sim data 1 năm (3/5/10GB) | B13: 8 | C13: =COUNTIF('02_Tra_Luna'!$A:$A,$A13) -> 0 | D13: =B13-C13 -> 8 | E13: =COUNTIF('04_Khach_le_CTV'!$A:$A,$A13) -> 8 | F13: =COUNTIF('05_Dai_ly'!$A:$A,$A13) -> 0 | G13: =COUNTIF('06_Cho_co_dinh'!$A:$A,$A13) -> 0 | H13: =COUNTIF('07_Cho_kich_hoat'!$A:$A,$A13) -> 0 | I13: =COUNTIF('08_Can_thu_hoi'!$A:$A,$A13) -> 0 | J13: =SUM(E13:I13) -> 8 | K13: =D13-J13 -> 0 | L13: =COUNTIF('09_Kho_Viet_Nam'!$A:$A,$A13) -> 0 | M13: =COUNTIFS('10_Kho_Takanoba'!$A:$A,$A13,'10_Kho_Takanoba'!$E:$E,"") -> 0 | N13: =COUNTIFS('11_Kho_Ibaraki'!$A:$A,$A13,'11_Kho_Ibaraki'!$G:$G,"") -> 0 | O13: =COUNTIFS('12_Ibaraki_da_ban'!$A:$A,$A13,'12_Ibaraki_da_ban'!$E:$E,"") -> 0 | P13: =SUM(L13:O13) -> 0 | Q13: =K13-P13 -> 0 | R13: =COUNTIFS('13_Sim_tra_nha_mang'!$A:$A,$A13,'13_Sim_tra_nha_mang'!$F:$F,"") -> 0 | S13: =COUNTIFS('14_Sim_da_huy'!$A:$A,$A13,'14_Sim_da_huy'!$F:$F,"") -> 0 | T13: =COUNTIFS('15_Doi_tac_de_lai'!$A:$A,$A13,'15_Doi_tac_de_lai'!$E:$E,"") -> 0 | U13: =COUNTIFS('16_Xuat_dai_ly'!$A:$A,$A13,'16_Xuat_dai_ly'!$H:$H,"") -> 0 | V13: =COUNTIFS('17_Khong_thay_nhap_kho'!$A:$A,$A13,'17_Khong_thay_nhap_kho'!$E:$E,"") -> 0 | W13: =COUNTIFS('18_Hong_tra_NCC'!$A:$A,$A13,'18_Hong_tra_NCC'!$E:$E,"") -> 0 | X13: =SUM(R13:W13) -> 0 | Y13: =Q13-X13 -> 0
A14: U3 | B14: 1 | C14: =COUNTIF('02_Tra_Luna'!$A:$A,$A14) -> 0 | D14: =B14-C14 -> 1 | E14: =COUNTIF('04_Khach_le_CTV'!$A:$A,$A14) -> 1 | F14: =COUNTIF('05_Dai_ly'!$A:$A,$A14) -> 0 | G14: =COUNTIF('06_Cho_co_dinh'!$A:$A,$A14) -> 0 | H14: =COUNTIF('07_Cho_kich_hoat'!$A:$A,$A14) -> 0 | I14: 0 | J14: =SUM(E14:I14) -> 1 | K14: =D14-J14 -> 0 | L14: =COUNTIF('09_Kho_Viet_Nam'!$A:$A,$A14) -> 0 | M14: =COUNTIFS('10_Kho_Takanoba'!$A:$A,$A14,'10_Kho_Takanoba'!$E:$E,"") -> 0 | N14: =COUNTIFS('11_Kho_Ibaraki'!$A:$A,$A14,'11_Kho_Ibaraki'!$G:$G,"") -> 0 | O14: =COUNTIFS('12_Ibaraki_da_ban'!$A:$A,$A14,'12_Ibaraki_da_ban'!$E:$E,"") -> 0 | P14: =SUM(L14:O14) -> 0 | Q14: =K14-P14 -> 0 | R14: =COUNTIFS('13_Sim_tra_nha_mang'!$A:$A,$A14,'13_Sim_tra_nha_mang'!$F:$F,"") -> 0 | S14: =COUNTIFS('14_Sim_da_huy'!$A:$A,$A14,'14_Sim_da_huy'!$F:$F,"") -> 0 | T14: =COUNTIFS('15_Doi_tac_de_lai'!$A:$A,$A14,'15_Doi_tac_de_lai'!$E:$E,"") -> 0 | U14: 0 | V14: =COUNTIFS('17_Khong_thay_nhap_kho'!$A:$A,$A14,'17_Khong_thay_nhap_kho'!$E:$E,"") -> 0 | W14: =COUNTIFS('18_Hong_tra_NCC'!$A:$A,$A14,'18_Hong_tra_NCC'!$E:$E,"") -> 0 | X14: =SUM(R14:W14) -> 0 | Y14: =Q14-X14 -> 0
A15: TỔNG | B15: =SUM(B6:B14) -> 6861 | C15: =SUM(C6:C14) -> 2000 | D15: =SUM(D6:D14) -> 4861 | E15: =SUM(E6:E14) -> 1262 | F15: =SUM(F6:F14) -> 258 | G15: =SUM(G6:G14) -> 152 | H15: =SUM(H6:H14) -> 14 | I15: =SUM(I6:I14) -> 421 | ... Y15: =SUM(Y6:Y14) -> 0
E16: ok | F16: ok | G16: ok | H16: ok | I16: ok | L16: ok | M16: ok | N16: ok | O16: ok | R16: ok | S16: ok | T16: ok | U16: ok | V16: ok | W16: ok
A29: CÁC SHEET MÃ CHI TIẾT (bấm để mở): | B29: Số dòng
A30: 01_Nhap_hang | B30: =COUNTA('01_Nhap_hang'!A:A)-1 -> 6852 | C30: (1) Toàn bộ IMEI/số sim nhập
A31: 02_Tra_Luna | B31: =COUNTA('02_Tra_Luna'!A:A)-1 -> 2000 | C31: (2) 2.000 IMEI U20 trả Luna
A32: 04_Khach_le_CTV | B32: =COUNTA('04_Khach_le_CTV'!A:A)-1 -> 1262 | C32: (4) Khách lẻ + CTV đang dùng
A33: 05_Dai_ly | B33: =COUNTA('05_Dai_ly'!A:A)-1 -> 258 | C33: (5) Đại lý đang dùng
A34: 06_Cho_co_dinh | B34: =COUNTA('06_Cho_co_dinh'!A:A)-1 -> 152 | C34: (6) Dùng chờ cố định
A35: 07_Cho_kich_hoat | B35: =COUNTA('07_Cho_kich_hoat'!A:A)-1 -> 14 | C35: (7) Chờ kích hoạt / chờ hủy
A36: 08_Can_thu_hoi | B36: =COUNTA('08_Can_thu_hoi'!A:A)-1 -> 482 | C36: (8) Cần thu hồi thực tế (file PM)
A37: 09_Kho_Viet_Nam | B37: =COUNTA('09_Kho_Viet_Nam'!A:A)-1 -> 583 | C37: (9) Tồn kho Việt Nam
A38: 10_Kho_Takanoba | B38: =COUNTA('10_Kho_Takanoba'!A:A)-1 -> 746 | C38: (10) Kiểm kho thực tế Takanoba 24/09
A39: 11_Kho_Ibaraki | B39: =COUNTA('11_Kho_Ibaraki'!A:A)-1 -> 32 | C39: (11) Tồn kho Ibaraki còn trong kho
A40: 12_Ibaraki_da_ban | B40: =COUNTA('12_Ibaraki_da_ban'!A:A)-1 -> 375 | C40: (12) Ibaraki đã bán chưa nhập PM
A41: 13_Sim_tra_nha_mang | B41: =COUNTA('13_Sim_tra_nha_mang'!A:A)-1 -> 232 | C41: (13) Sim trả lại nhà mạng
A42: 14_Sim_da_huy | B42: =COUNTA('14_Sim_da_huy'!A:A)-1 -> 616 | C42: (14) Sim đã hủy (1 dòng/mã)
A43: 15_Doi_tac_de_lai | B43: =COUNTA('15_Doi_tac_de_lai'!A:A)-1 -> 16 | C43: (15) Đối tác để lại (sim / cục)
A44: 16_Xuat_dai_ly | B44: =COUNTA('16_Xuat_dai_ly'!A:A)-1 -> 220 | C44: (16) Xuất đại lý đã hủy chưa thu hồi
A45: 17_Khong_thay_nhap_kho | B45: =COUNTA('17_Khong_thay_nhap_kho'!A:A)-1 -> 11 | C45: (17) Không thấy nhập kho / Kiểm kho không thấy (đã gộp)
A46: 18_Hong_tra_NCC | B46: =COUNTA('18_Hong_tra_NCC'!A:A)-1 -> 10 | C46: (18) Hỏng / trả nhà cung cấp

Sheet 01_Nhap_hang
A1: Nhóm | B1: Mã (IMEI / Số sim) | C1: Loại mã | D1: Sheet nguồn
A2: U20 | B2: 861720051171636 | C2: IMEI | D2: U20
A3: U20 | B3: 861720051172071 | C3: IMEI | D3: U20
A4: U20 | B4: 861720051173137 | C4: IMEI | D4: U20
A5: U20 | B5: 861720051178771 | C5: IMEI | D5: U20
A6: U20 | B6: 861720051182393 | C6: IMEI | D6: U20
A7: U20 | B7: 861720051183797 | C7: IMEI | D7: U20
A8: U20 | B8: 861720051184357 | C8: IMEI | D8: U20
A9: U20 | B9: 861720051186758 | C9: IMEI | D9: U20
A10: U20 | B10: 861720051189331 | C10: IMEI | D10: U20
A11: U20 | B11: 861720051147958 | C11: IMEI | D11: U20
A12: U20 | B12: 861720051133891 | C12: IMEI | D12: U20
... A6853: SB 50GB | B6853: 8036683145 | C6853: Số sim | D6853: SB 50GB

Sheet 02_Tra_Luna
A1: Nhóm | B1: IMEI
A2: U20 | B2: 861720051166495
A3: U20 | B3: 861720051148030
A4: U20 | B4: 861720051154210
A5: U20 | B5: 861720051154251
A6: U20 | B6: 861720051180371
A7: U20 | B7: 861720051184472
A8: U20 | B8: 861720051179530
A9: U20 | B9: 861720051175579
A10: U20 | B10: 861720051174994
A11: U20 | B11: 861720051170695
A12: U20 | B12: 861720051161215
... A2001: U20 | B2001: 861720051244359

Sheet 04_Khach_le_CTV
A1: Nhóm | B1: Sản phẩm (gốc) | C1: Mã thiết bị | D1: MSN (SĐT) | E1: Khách hàng | F1: Mã KH | G1: Mã DVKH | H1: Mã đơn hàng
A2: MR1 | B2: Wifi full dung lượng MR1 | C2: 355185373386028 | D2: - | E2: May Thiri | F2: KH03912 | G2: DV04845 | H2: DH04554
A3: U20 | B3: Wifi 100GB U20 | C3: 861720051157056 | D3: - | E3: Jher バウン Jr. | F3: KH03905 | G3: DV04837 | H3: DH04544
A4: U20 | B4: Wifi full dung lượng U20 | C4: 861720051164490 | D4: - | E4: Nirmal Dhanushka | F4: KH03904 | G4: DV04835 | H4: DH04543
A5: U20 | B5: Wifi full dung lượng U20 | C5: 861720051179050 | D5: - | E5: Glainess Marie Gemperoso | F5: KH03903 | G5: DV04832 | H5: DH04539
A6: WIMAX | B6: Wifi WIMAX | C6: 356221183463373 | D6: - | E6: Joyce Vega | F6: KH03896 | G6: DV04831 | H6: DH04538
A7: MR1 | B7: Wifi full dung lượng MR1 | C7: 355185373388909 | D7: - | E7: Ann Ann | F7: KH03902 | G7: DV04830 | H7: DH04534
A8: U20 | B8: Wifi full dung lượng U20 | C8: 861720051141191 | D8: - | E8: Trân Trân | F8: KH03900 | G8: DV04826 | H8: DH04531
A9: U20 | B9: Wifi full dung lượng U20 | C9: 861720051183656 | D9: - | E9: Rabbi Md Naim Hossain | F9: KH03899 | G9: DV04825 | H9: DH04533
A10: U20 | B10: Wifi 100GB U20 | C10: 861720051168491 | D10: - | E10: Marietta Kayukawa | F10: KH03901 | G10: DV04824 | H10: DH04532
A11: U20 | B11: Wifi full dung lượng U20 | C11: 861720051152974 | D11: - | E11: Jayan Thisaru | F11: KH01907 | G11: DV04823 | H11: DH04529
A12: MR1 | B12: Wifi full dung lượng MR1 | C12: 355185373608405 | D12: - | E12: Roque Penion | F12: KH03898 | G12: DV04822 | H12: DH04528
... A1261: U20 | B1261: Wifi full dung lượng U20 | C1261: 861720051169697 | D1261: - | E1261: Hoàng Đoàn | F1261: KH00232 | G1261: DV00022 | H1261: DH00022
A1262: U20 | B1262: (KT bổ sung) | C1262: 861720051166057 | D1262: - | E1262: KT bổ sung 24/09: khách lẻ quản lý (KT ghi 86172005116605 - thiếu 1 số, khớp duy nhất mã này trong DS cần tìm)
A1263: U20 | B1263: (KT bổ sung) | C1263: 861720051273580 | D1263: - | E1263: KT bổ sung 24/09: chuyển vào khách lẻ đang quản lý

Sheet 05_Dai_ly
A1: Nhóm | B1: Sản phẩm (gốc) | C1: Mã thiết bị | D1: MSN (SĐT) | E1: Khách hàng | F1: Mã KH | G1: Mã DVKH | H1: Mã đơn hàng
A2: SB 100GB | B2: Sim softbank 100GB | C2: 8071152816 | D2: - | E2: CTV Hồng | F2: KH00385 | G2: DV04141 | H2: DH04516
A3: SB 100GB | B3: Sim softbank 100GB | C3: 8070983904 | D3: - | E3: CTV Hồng | F3: KH00385 | G3: DV04140 | H3: DH04516
A4: SB 100GB | B4: Sim softbank 100GB | C4: 7065787814 | D4: - | E4: CTV Hồng | F4: KH00385 | G4: DV04139 | H4: DH04516
A5: SB 100GB | B5: Sim softbank 100GB | C5: 8071338033 | D5: - | E5: CTV Hồng | F5: KH00385 | G5: DV04138 | H5: DH04516
A6: SB 100GB | B6: Sim softbank 100GB | C6: 8046165708 | D6: - | E6: CTV Hồng | F6: KH00385 | G6: DV04137 | H6: DH04516
A7: SB 100GB | B7: Sim softbank 100GB | C7: 8074662482 | D7: - | E7: CTV Hồng | F7: KH00385 | G7: DV04136 | H7: DH04516
A8: SB 100GB | B8: Sim softbank 100GB | C8: 9084917212 | D8: - | E8: CTV Hồng | F8: KH00385 | G8: DV04135 | H8: DH04516
A9: U20 | B9: Wifi full dung lượng U20 | C9: 861720051187517 | D9: - | E9: CTV Hồng | F9: KH00385 | G9: DV04134 | H9: DH04517
A10: U20 | B10: Wifi full dung lượng U20 | C10: 861720051146117 | D10: - | E10: Công ty Teki - A Duân | F10: KH00518 | G10: DV04039 | H10: DH04377
A11: U20 | B11: Wifi full dung lượng U20 | C11: 861720051137314 | D11: - | E11: Công ty Teki - A Duân | F11: KH00518 | G11: DV04036 | H11: DH04377
A12: U20 | B12: Wifi full dung lượng U20 | C12: 861720051161819 | D12: - | E12: Công ty Teki - A Duân | F12: KH00518 | G12: DV04035 | H12: DH04377
... A259: Datacall vật lý | B259: Sim datacall vật lý | C259: 08080783346 | D259: - | E259: Đại lý Trưởng | F259: KH00244 | G259: DV00651 | H259: DH00651

Sheet 06_Cho_co_dinh
A1: Nhóm | B1: Tên sản phẩm (gốc) | C1: Mã thiết bị | D1: Mã dịch vụ | E1: Tên khách hàng | F1: Người phụ trách | G1: Đại lý nội bộ | H1: Mã đơn hàng
A2: U20 | B2: Wifi 100GB U20 | C2: 861720051142017 | D2: DV04862 | E2: Coffee Gafair | F2: Lê Quốc Khánh | G2: ĐLý Việt | H2: DH04573
A3: U20 | B3: Wifi 100GB U20 | C3: 861720051140730 | D3: DV04859 | E3: Ernest Ampofo | F3: Nguyễn Kiêm Hoàng | G3: ĐLý Hoàng | H3: DH04570
A4: U20 | B4: Wifi 100GB U20 | C4: 861720051173459 | D4: DV04858 | E4: Hara Melane Galope | F4: Lê Quốc Khánh | G4: ĐLý Việt | H4: DH04566
A5: U20 | B5: Wifi 100GB U20 | C5: 861720051133271 | D5: DV04856 | E5: Tony Tanaka | F5: Nguyễn Thị Phương Thảo | G5: ĐLý Hoàng | H5: DH04567
A6: U20 | B6: Wifi 100GB U20 | C6: 861720051168210 | D6: DV04855 | E6: Đại Lý Kiên- Hữu Hoàng | F6: Nguyễn Thị Hoa | G6: đại lý Hoa | H6: DH04562
A7: U20 | B7: Wifi 100GB U20 | C7: 861720051178854 | D7: DV04854 | E7: Đại Lý Kiên- Hữu Hoàng | F7: Nguyễn Thị Hoa | G7: đại lý Hoa | H7: DH04561
A8: U20 | B8: Wifi 100GB U20 | C8: 861720051146752 | D8: DV04844 | E8: Đại Lý Kiên- Hữu Hoàng | F8: Nguyễn Thị Hoa | G8: đại lý Hoa | H8: DH04551
A9: U20 | B9: Wifi 100GB U20 | C9: 861720051133057 | D9: DV04843 | E9: You Mbeng | F9: Lê Quốc Khánh | G9: ĐLý Việt | H9: DH04550
A10: U20 | B10: Wifi 100GB U20 | C10: 861720051178250 | D10: DV04841 | E10: Đại Lý Kiên- Hữu Hoàng | F10: Nguyễn Thị Hoa | G10: đại lý Hoa | H10: DH04547
A11: U20 | B11: Wifi 100GB U20 | C11: 861720051161595 | D11: DV04840 | E11: Truong Le | F11: Nguyễn Thị Phương Thảo | G11: ĐLý Hoàng | H11: DH04545
A12: U20 | B12: Wifi full dung lượng U20 | C12: 861720051151075 | D12: DV04836 | E12: Saru Matsumura | F12: Trương Xuân Dũng | G12: ĐLý Việt | H12: DH04542
... A56: U20 | B56: Wifi full dung lượng U20 | C56: 861720051178110 | D56: DV04652 | E56: Đại lý Kiên- Luân JP | F56: Nguyễn Thị Hoa | G56: ĐLý tecno | H56: DH04091
A57: U20 | B57: Wifi full dung lượng U20 | C57: 861720051176015 | D57: DV04629 | E57: tài cao | F57: Nguyễn Thị Hoa | H57: DH04009
A58: U20 | B58: Wifi full dung lượng U20 | C58: 861720051175355 | D58: DV04625 | E58: Nakandakari Morino Héctor | F58: Nguyễn Đức Phương | G58: ĐLý tecno | H58: DH04151
A59: U20 | B59: Wifi full dung lượng U20 | C59: 861720051175272 | D59: DV04623 | E59: Đại lý Kiên- Luân JP | F59: Nguyễn Thị Hoa | G59: ĐLý tecno | H59: DH04024
A60: U20 | B60: Wifi full dung lượng U20 | C60: 861720051174358 | D60: DV04615 | E60: Juka Sasaki | F60: Trương Xuân Dũng | G60: ĐLý Việt | H60: DH04044
A61: U20 | B61: Wifi full dung lượng U20 | C61: 861720051173855 | D61: DV04610 | E61: Dreads Shevo | F61: Trương Xuân Dũng | G61: ĐLý Việt | H61: DH04027
A62: U20 | B62: Wifi full dung lượng U20 | C62: 861720051173376 | D62: DV04607 | E62: Min Kyaw Tun | F62: Trương Xuân Dũng | G62: ĐLý Việt | H62: DH04394
A63: U20 | B63: Wifi full dung lượng U20 | C63: 861720051172519 | D63: DV04597 | E63: Yuuta Masuda | F63: Lê Quốc Khánh | G63: ĐLý Việt | H63: DH04282
A64: U20 | B64: Wifi full dung lượng U20 | C64: 861720051172378 | D64: DV04596 | E64: Đại Lý Kiên- Sơn Tùng | F64: Nguyễn Thị Hoa | G64: ĐLý tecno | H64: DH04141
A65: U20 | B65: Wifi full dung lượng U20 | C65: 861720051172014 | D65: DV04594 | E65: Ali Mamun | F65: Nguyễn Việt Hoàng | G65: ĐLý Hoàng | H65: DH04198
A66: U20 | B66: Wifi full dung lượng U20 | C66: 861720051171859 | D66: DV04589 | E66: Marappullige sameera pathum | F66: Nguyễn Đức Phương | G66: ĐLý tecno | H66: DH04265
A67: U20 | B67: Wifi full dung lượng U20 | C67: 861720051171396 | D67: DV04581 | E67: Đại Lý Kiên- Sơn Tùng | F67: Nguyễn Thị Hoa | G67: đại lý Hoa | H67: DH04358
A68: U20 | B68: Wifi full dung lượng U20 | C68: 861720051170976 | D68: DV04579 | E68: Đại lý Kiên- Dưa | F68: Nguyễn Thị Hoa | G68: đại lý Hoa | H68: DH04374
A69: U20 | B69: Wifi full dung lượng U20 | C69: 861720051170612 | D69: DV04570 | E69: Jocelyn Castro Saito | F69: Trương Xuân Dũng | G69: ĐLý Việt | H69: DH04406
... A105: U20 | B105: Wifi full dung lượng U20 | C105: 861720051153576 | D105: DV04394 | E105: Đại lý AKIKO | F105: Nguyễn Thị Hoa | G105: ĐLý tecno | H105: DH04277
A106: U20 | B106: Wifi full dung lượng U20 | C106: 861720051153550 | D106: DV04393 | E106: Hnin Thiri Htun | F106: Trương Xuân Dũng | H106: DH03681
A107: U20 | B107: Wifi full dung lượng U20 | C107: 861720051153139 | D107: DV04392 | E107: Đại lý AKIKO | F107: Nguyễn Thị Hoa | G107: ĐLý tecno | H107: DH04316
A108: U20 | B108: Wifi full dung lượng U20 | C108: 861720051152156 | D108: DV04381 | E108: LINTON LEVIN | F108: Nguyễn Đức Phương | G108: ĐLý tecno | H108: DH04393
A109: U20 | B109: Wifi full dung lượng U20 | C109: 861720051151976 | D109: DV04379 | E109: Maqshood Ali | F109: Lê Quốc Khánh | G109: ĐLý Việt | H109: DH04032
A110: U20 | B110: Wifi full dung lượng U20 | C110: 861720051151612 | D110: DV04376 | E110: Đại lý Kiên- Dưa | F110: Nguyễn Thị Hoa | G110: đại lý Hoa | H110: DH04328
A111: U20 | B111: Wifi full dung lượng U20 | C111: 861720051151430 | D111: DV04371 | E111: Farasat Khan | F111: Nguyễn Đình Việt | G111: ĐLý Việt | H111: DH04153
A112: U20 | B112: Wifi full dung lượng U20 | C112: 861720051151356 | D112: DV04368 | E112: Løvè Castillo | F112: Trương Xuân Dũng | G112: ĐLý Việt | H112: DH04309
A113: U20 | B113: Wifi full dung lượng U20 | C113: 861720051151216 | D113: DV04366 | E113: Đại lý AKIKO | F113: Nguyễn Thị Hoa | G113: ĐLý tecno | H113: DH04278
A114: U20 | B114: Wifi full dung lượng U20 | C114: 861720051151034 | D114: DV04359 | E114: Mamadou Cissé | F114: Nguyễn Đức Phương | G114: ĐLý tecno | H114: DH04197
A115: U20 | B115: Wifi full dung lượng U20 | C115: 861720051150952 | D115: DV04354 | E115: Richard Danao | F115: Trương Xuân Dũng | G115: ĐLý Việt | H115: DH04123
A116: U20 | B116: Wifi full dung lượng U20 | C116: 861720051150937 | D116: DV04353 | E116: Nt Oanh | F116: Nguyễn Thị Phương Thảo | G116: ĐLý Hoàng | H116: DH04136
A117: U20 | B117: Wifi full dung lượng U20 | C117: 861720051150655 | D117: DV04346 | E117: Đại Lý Kiên- Sơn Tùng | F117: Nguyễn Thị Hoa | G117: đại lý Hoa | H117: DH04449
A118: U20 | B118: Wifi full dung lượng U20 | C118: 861720051150630 | D118: DV04343 | E118: Sajith Rangana | F118: Lê Quốc Khánh | G118: ĐLý Việt | H118: DH04216
...

Sheet 07_Cho_kich_hoat
A1: Nhóm | B1: Sản phẩm (gốc) | C1: Mã thiết bị | D1: MSN (SĐT) | E1: Khách hàng | F1: Mã KH | G1: Mã DVKH | H1: Mã đơn hàng
A2: MR1 | B2: Wifi full dung lượng MR1 | C2: 355185372304022 | D2: - | E2: Estrella Aaron Nino Coloma | F2: KH03931 | G2: DV04863 | H2: DH04575
A3: MR1 | B3: Wifi full dung lượng MR1 | C3: 355185372203588 | D3: - | E3: Eddy Subroto Taruno | F3: KH03926 | G3: DV04861 | H3: DH04571
A4: U20 | B4: Wifi full dung lượng U20 | C4: 861720051145838 | D4: - | E4: Maria Crisanta Vidad | F4: KH03924 | G4: DV04857 | H4: DH04568
A5: U20 | B5: Wifi full dung lượng U20 | C5: 861720051191758 | D5: - | E5: Jay Benavente | F5: KH03920 | G5: DV04853 | H5: DH04565
A6: U20 | B6: Wifi 100GB U20 | C6: 861720051140839 | D6: - | E6: Emerichlyn Akina May Arcaya | F6: KH03919 | G6: DV04852 | H6: DH04564
A7: MR1 | B7: Wifi full dung lượng MR1 | C7: 355185372226621 | D7: - | E7: Manggob Sheena Jay | F7: KH03913 | G7: DV04851 | H7: DH04555
A8: MR1 | B8: Wifi full dung lượng MR1 | C8: 355185373361435 | D8: - | E8: Pramodh Chathu | F8: KH03918 | G8: DV04850 | H8: DH04560
A9: MR1 | B9: Wifi full dung lượng MR1 | C9: 355185373431527 | D9: - | E9: Lawrence Gonzales | F9: KH03917 | G9: DV04849 | H9: DH04559
A10: U20 | B10: Wifi 100GB U20 | C10: 861720051136258 | D10: - | E10: VILLAR CRISTIAN BOY LAVARO | F10: KH03916 | G10: DV04848 | H10: DH04558
A11: U20 | B11: Wifi full dung lượng U20 | C11: 861720051257153 | D11: - | E11: Irenea Sawal | F11: KH03915 | G11: DV04847 | H11: DH04557
A12: MR1 | B12: Wifi full dung lượng MR1 | C12: 355185373464957 | D12: - | E12: Jessabel V. Oriendo | F12: KH03744 | G12: DV04846 | H12: DH04556
... A14: U20 | B14: Wifi full dung lượng U20 | C14: 861720051193135 | D14: - | E14: Buda Artha | F14: KH01713 | G14: DV02867 | H14: DH02773
A15: MR1 | B15: (KT bổ sung) | C15: 355185373693308 | D15: -

Sheet 08_Can_thu_hoi
A1: Nhóm | B1: Tên sản phẩm (gốc) | C1: Mã thiết bị | D1: Mã KH | E1: Khách hàng | F1: Nhóm khách hàng
A2: U20 | B2: Wifi 100GB U20 | C2: 861720051150275 | D2: KH03882 | E2: Luke Ford | F2: NHÓM KHÁCH HÀNG LẺ
A3: U20 | B3: Wifi 100GB U20 | C3: 861720051172097 | D3: KH03872 | E3: Naigah mercy ndifang | F3: NHÓM KHÁCH HÀNG ĐẠI LÝ
A4: U20 | B4: Wifi 100GB U20 | C4: 861720051151174 | D4: KH03824 | E4: Abitu Theron | F4: NHÓM KHÁCH HÀNG WF CỐ ĐỊNH
A5: U20 | B5: Wifi 100GB U20 | C5: 861720051175132 | D5: KH03807 | E5: Samuel Kesse | F5: NHÓM KHÁCH HÀNG WF CỐ ĐỊNH
A6: U20 | B6: Wifi full dung lượng U20 | C6: 861720051188572 | D6: KH02322 | E6: Đại lý Kiên- Luân JP | F6: NHÓM KHÁCH HÀNG WF CỐ ĐỊNH
A7: U20 | B7: Wifi full dung lượng U20 | C7: 861720051141332 | D7: KH03788 | E7: Decena Fermasaineh | F7: NHÓM KHÁCH HÀNG WF CỐ ĐỊNH
A8: U20 | B8: Wifi full dung lượng U20 | C8: 861720051169291 | D8: KH02600 | E8: Đại lý AKIKO | F8: NHÓM KHÁCH HÀNG WF CỐ ĐỊNH
A9: MR1 | B9: Wifi full dung lượng MR1 | C9: 355185372247338 | D9: KH03398 | E9: Tuấn Phạm | F9: NHÓM KHÁCH HÀNG LẺ
A10: MR1 | B10: Wifi full dung lượng MR1 | C10: 355185373291442 | D10: KH03747 | E10: Nguyễn Hương | F10: NHÓM KHÁCH HÀNG LẺ
A11: U20 | B11: Wifi full dung lượng U20 | C11: 861720051148279 | D11: KH03733 | E11: Srluisa Bautista | F11: NHÓM KHÁCH HÀNG WF CỐ ĐỊNH
A12: U20 | B12: Wifi full dung lượng U20 | C12: 861720051170331 | D12: KH02322 | E12: Đại lý Kiên- Luân JP | F12: NHÓM KHÁCH HÀNG WF CỐ ĐỊNH
... A477: U3 | B477: Wifi full dung lượng U3 | C477: 869714043432547 | D477: KH00276 | E477: Nguyễn Văn Mạnh | F477: NHÓM KHÁCH HÀNG LẺ
A478: U20 | B478: (KT bổ sung) | C478: 861720051152016
A479: U20 | B479: (KT bổ sung) | C479: 861720051153113
A480: U20 | B480: (KT bổ sung) | C480: 861720051165836
A481: U20 | B481: (KT bổ sung) | C481: 861720051146059
A482: U20 | B482: (KT bổ sung) | C482: 861720051146570
A483: U20 | B483: (KT bổ sung) | C483: 861720051135136

Sheet 09_Kho_Viet_Nam
A1: Nhóm | B1: Loại sản phẩm (gốc) | C1: Mã thiết bị | D1: Kho | E1: Trạng thái thiết bị | F1: Mã phiếu nhập kho | G1: Đã bán chưa nhập PM (chuyển sang cột riêng, không tính ở đây)
A2: U20 | B2: Wifi full dung lượng U20 | C2: 861720051183417 | D2: Văn phòng V1-A02 | E2: Tốt | F2: PNK06497
A3: U20 | B3: Wifi full dung lượng U20 | C3: 861720051170117 | D3: Văn phòng V1-A02 | E3: Tốt | F3: PNK06439
A4: U20 | B4: Wifi full dung lượng U20 | C4: 861720051133537 | D4: Văn phòng V1-A02 | E4: Tốt | F4: INV-LEGACY-2
A5: U20 | B5: Wifi full dung lượng U20 | C5: 861720051133891 | D5: Văn phòng V1-A02 | E5: Tốt | F5: INV-LEGACY-2
A6: U20 | B6: Wifi full dung lượng U20 | C6: 861720051134436 | D6: Văn phòng V1-A02 | E6: Tốt | F6: INV-LEGACY-2
A7: U20 | B7: Wifi full dung lượng U20 | C7: 861720051134576 | D7: Văn phòng V1-A02 | E7: Tốt | F7: INV-LEGACY-2
A8: U20 | B8: Wifi full dung lượng U20 | C8: 861720051134899 | D8: Văn phòng V1-A02 | E8: Tốt | F8: INV-LEGACY-2
A9: U20 | B9: Wifi full dung lượng U20 | C9: 861720051135052 | D9: Văn phòng V1-A02 | E9: Tốt | F9: INV-LEGACY-2
A10: U20 | B10: Wifi full dung lượng U20 | C10: 861720051135110 | D10: Văn phòng V1-A02 | E10: Tốt | F10: INV-LEGACY-2
A11: U20 | B11: Wifi full dung lượng U20 | C11: 861720051135151 | D11: Văn phòng V1-A02 | E11: Tốt | F11: INV-LEGACY-2
A12: U20 | B12: Wifi full dung lượng U20 | C12: 861720051136357 | D12: Văn phòng V1-A02 | E12: Tốt | F12: INV-LEGACY-2
A13: U20 | B13: Wifi full dung lượng U20 | C13: 861720051136373 | D13: Văn phòng V1-A02 | E13: Tốt | F13: INV-LEGACY-2
... A584: U20 | B584: Wifi full dung lượng U20 | C584: 861720051133198 | D584: Văn phòng Technopark | E584: Tốt | F584: PNK02160

Sheet 10_Kho_Takanoba
A1: Nhóm | B1: Mã (IMEI / số sim) | C1: Vị trí trong file (sheet / dòng / cột) | D1: Có trong DS nhập? | E1: Đang ở sổ khác (không tính) | F1: Ghi chú
A2: MR1 | B2: 355185372283853 | C2: Sheet1 (2) / dòng 2 / cột B | D2: Có
A3: MR1 | B3: 355185372266148 | C3: Sheet1 (2) / dòng 2 / cột C | D3: Có
A4: MR1 | B4: 355185372148429 | C4: Sheet1 (2) / dòng 2 / cột E | D4: Có
A5: MR1 | B5: 355185372152454 | C5: Sheet1 (2) / dòng 2 / cột F | D5: Có
A6: MR1 | B6: 355185372160622 | C6: Sheet1 (2) / dòng 2 / cột G | D6: Có
A7: MR1 | B7: 355185372333039 | C7: Sheet1 (2) / dòng 2 / cột H | D7: Có
A8: MR1 | B8: 355185372291138 | C8: Sheet1 (2) / dòng 2 / cột I | D8: Có
A9: MR1 | B9: 355185372218081 | C9: Sheet1 (2) / dòng 2 / cột J | D9: Có
A10: MR1 | B10: 355185372146662 | C10: Sheet1 (2) / dòng 2 / cột K | D10: Có
A11: MR1 | B11: 355185372180760 | C11: Sheet1 (2) / dòng 2 / cột L | D11: Có
A12: MR1 | B12: 355185372135962 | C12: Sheet1 (2) / dòng 2 / cột M | D12: Có
A13: MR1 | B13: 355185372149666 | C13: Sheet1 (2) / dòng 3 / cột E | D13: Có
... A451: Datacall vật lý | B451: 8023947565 | C451: Sheet1 / dòng 2 / cột K | D451: Có
A452: SB 100GB | B452: 8075718044 | C452: Sheet1 / dòng 2 / cột L | D452: Có | F452: Sim đã hủy nhưng phát hành lại, nay ở kho (KT xác nhận 24/09) - đếm ở đây, bỏ khỏi Sim đã hủy
A453: U20 | B453: 861720051166099 | C453: Sheet1 / dòng 3 / cột A | D453: Có
A454: U20 | B454: 861720051145812 | C454: Sheet1 / dòng 3 / cột B | D454: Có
A455: U20 | B455: 861720051174234 | C455: Sheet1 / dòng 3 / cột C | D455: Có
A456: U20 | B456: 861720051149350 | C456: Sheet1 / dòng 3 / cột D | D456: Có
A457: U20 | B457: 861720051179498 | C457: Sheet1 / dòng 3 / cột E | D457: Có
A458: U20 | B458: 861720051136472 | C458: Sheet1 / dòng 3 / cột F | D458: Có
A459: U20 | B459: 861720051185057 | C459: Sheet1 / dòng 3 / cột G | D459: Có
A460: WIMAX | B460: 356221183717190 | C460: Sheet1 / dòng 3 / cột I | D460: Có
A461: Datacall vật lý | B461: 9095225525 | C461: Sheet1 / dòng 3 / cột K | D461: Có
A462: SB 100GB | B462: 8074563141 | C462: Sheet1 / dòng 3 / cột L | D462: Có | F462: Sim đã hủy nhưng phát hành lại, nay ở kho (KT xác nhận 24/09) - đếm ở đây, bỏ khỏi Sim đã hủy
A463: U20 | B463: 861720051193739 | C463: Sheet1 / dòng 4 / cột A | D463: Có
A464: U20 | B464: 861720051139914 | C464: Sheet1 / dòng 4 / cột B | D464: Có
A465: U20 | B465: 861720051157072 | C465: Sheet1 / dòng 4 / cột C | D465: Có
A466: U20 | B466: 861720051164797 | C466: Sheet1 / dòng 4 / cột D | D466: Có
A467: U20 | B467: 861720051180835 | C467: Sheet1 / dòng 4 / cột E | D467: Có
A468: U20 | B468: 861720051140698 | C468: Sheet1 / dòng 4 / cột F | D468: Có
A469: U20 | B469: 861720051165273 | C469: Sheet1 / dòng 4 / cột G | D469: Có
A470: U20 | B470: 861720051136514 | C470: Sheet1 / dòng 4 / cột H | D470: Có
A471: WIMAX | B471: 356221183719287 | C471: Sheet1 / dòng 4 / cột I | D471: Có
A472: Datacall vật lý | B472: 9015945600 | C472: Sheet1 / dòng 4 / cột K | D472: Có
A473: SB 100GB | B473: 8073665852 | C473: Sheet1 / dòng 4 / cột L | D473: Có | F473: Sim đã hủy nhưng phát hành lại, nay ở kho (KT xác nhận 24/09) - đếm ở đây, bỏ khỏi Sim đã hủy
A474: U20 | B474: 861720051143296 | C474: Sheet1 / dòng 5 / cột A | D474: Có
A475: U20 | B475: 861720051158534 | C475: Sheet1 / dòng 5 / cột B | D475: Có
A476: U20 | B476: 861720051158252 | C476: Sheet1 / dòng 5 / cột C | D476: Có
A477: U20 | B477: 861720051148311 | C477: Sheet1 / dòng 5 / cột D | D477: Có
...

Sheet 11_Kho_Ibaraki
A1: Nhóm | B1: Loại sản phẩm (gốc) | C1: Mã thiết bị | D1: Kho | E1: Trạng thái thiết bị | F1: Mã phiếu nhập kho | G1: Đã bán chưa nhập PM (chuyển sang cột riêng, không tính ở đây)
A2: U20 | B2: Wifi full dung lượng U20 | C2: 861720051153170 | D2: Ibaraki | E2: Tốt | F2: INV-LEGACY-4
A3: U20 | B3: Wifi full dung lượng U20 | C3: 861720051155811 | D3: Ibaraki | E3: Tốt | F3: INV-LEGACY-4
A4: U20 | B4: Wifi full dung lượng U20 | C4: 861720051169119 | D4: Ibaraki | E4: Tốt | F4: INV-LEGACY-4
A5: U20 | B5: Wifi full dung lượng U20 | C5: 861720051170877 | D5: Ibaraki | E5: Tốt | F5: INV-LEGACY-4
A6: U20 | B6: Wifi full dung lượng U20 | C6: 861720051171016 | D6: Ibaraki | E6: Tốt | F6: INV-LEGACY-4
A7: U20 | B7: Wifi full dung lượng U20 | C7: 861720051172055 | D7: Ibaraki | E7: Tốt | F7: INV-LEGACY-4
A8: U20 | B8: Wifi full dung lượng U20 | C8: 861720051174259 | D8: Ibaraki | E8: Tốt | F8: INV-LEGACY-4
A9: U20 | B9: Wifi full dung lượng U20 | C9: 861720051174291 | D9: Ibaraki | E9: Tốt | F9: INV-LEGACY-4
A10: U20 | B10: Wifi full dung lượng U20 | C10: 861720051175033 | D10: Ibaraki | E10: Tốt | F10: INV-LEGACY-4
A11: U20 | B11: Wifi full dung lượng U20 | C11: 861720051177070 | D11: Ibaraki | E11: Tốt | F11: INV-LEGACY-4
A12: U20 | B12: Wifi full dung lượng U20 | C12: 861720051177310 | D12: Ibaraki | E12: Tốt | F12: INV-LEGACY-4
A13: U20 | B13: Wifi full dung lượng U20 | C13: 861720051178516 | D13: Ibaraki | E13: Tốt | F13: INV-LEGACY-4
... A33: U20 | B33: Wifi full dung lượng U20 | C33: 861720051193655 | D33: Ibaraki | E33: Tốt | F33: INV-LEGACY-4

Sheet 12_Ibaraki_da_ban
A1: Nhóm | B1: Mã thiết bị (IMEI) | C1: Có trong DS nhập? | D1: Có trong tồn kho Ibaraki (PM)? | E1: Đang ở sổ khác ngoài kho Ibaraki (không tính)
A2: U20 | B2: 861720051132992 | C2: Có | D2: Có
A3: U20 | B3: 861720051133073 | C3: Có | D3: Có
A4: U20 | B4: 861720051133099 | C4: Có | D4: Có
A5: U20 | B5: 861720051133172 | C5: Có | D5: Có
A6: U20 | B6: 861720051133552 | C6: Có | D6: Có
A7: U20 | B7: 861720051133750 | C7: Có | D7: Có
A8: U20 | B8: 861720051133776 | C8: Có | D8: Có
A9: U20 | B9: 861720051134238 | C9: Có | D9: Có
A10: U20 | B10: 861720051134675 | C10: Có | D10: Có
A11: U20 | B11: 861720051134832 | C11: Có | D11: Có
A12: U20 | B12: 861720051134873 | C12: Có | D12: Có
A13: U20 | B13: 861720051135011 | C13: Có | D13: Có
... A351: U20 | B351: 861720051193754 | C351: Có | D351: Có
A352: U20 | B352: 861720051150911 | F352: Đã bán C Cash 3/2/2026
A353: U20 | B353: 861720051159698 | F353: Đã bán C Cash 3/2/2026
A354: U20 | B354: 861720051164870 | F354: Đã bán C Cash 3/2/2026
A355: U20 | B355: 861720051167535 | F355: Đã bán C Cash 3/2/2026
A356: U20 | B356: 861720051171115 | F356: Đã bán C Cash 3/2/2026
A357: U20 | B357: 861720051171735 | F357: Đã bán C Cash 3/2/2026
A358: U20 | B358: 861720051172410 | F358: Đã bán C Cash 3/2/2026
A359: U20 | B359: 861720051172618 | F359: Đã bán C cash, đang hỏi
A360: U20 | B360: 861720051173731 | F360: Đã bán C Cash 3/2/2026
A361: U20 | B361: 861720051173756 | F361: Đã bán C cash, đang hỏi
A362: U20 | B362: 861720051178813 | F362: Đã bán C Cash 3/2/2026
A363: U20 | B363: 861720051179118 | F363: Đã bán C Cash 3/2/2026
... A376: U20 | B376: 861720051190511 | F376: Đã bán C Cash 3/2/2026

Sheet 13_Sim_tra_nha_mang
A1: Nhóm | B1: Số sim | C1: Loại ghi trong file | D1: IMEI cục đi kèm (nếu có) | E1: Có trong DS nhập? | F1: Đang ở sổ khác (không tính)
A2: Datacall vật lý | B2: 8080780380 | C2: Sim vật lý | E2: Có
A3: Datacall vật lý | B3: 7044871577 | C3: Sim vật lý | E3: Có
A4: Datacall vật lý | B4: 7048168461 | C4: Sim vật lý | E4: Có
A5: Datacall vật lý | B5: 8025998197 | C5: Sim vật lý | D5: 861720051268705 | E5: Có
A6: Datacall vật lý | B6: 9041371351 | C6: Sim vật lý | E6: Có
A7: Datacall vật lý | B7: 7044615460 | C7: Sim vật lý | E7: Có
A8: Datacall vật lý | B8: 8084054367 | C8: Sim vật lý | E8: Có
A9: Datacall vật lý | B9: 8025998291 | C9: Sim vật lý | E9: Có
A10: Datacall vật lý | B10: 7044871536 | C10: Sim vật lý | E10: Có
A11: Datacall vật lý | B11: 7010550816 | C11: Sim vật lý | E11: Có
A12: Datacall vật lý | B12: 7048168351 | C12: Sim vật lý | E12: Có
A13: Datacall vật lý | B13: 7048168365 | C13: Sim vật lý | E13: Có
A14: Datacall vật lý | B14: 7044615560 | C14: Sim vật lý | E14: Có
A15: Datacall vật lý | B15: 8020769117 | C15: Sim vật lý | E15: Có
A16: Datacall vật lý | B16: 8095070289 | C16: Sim vật lý | E16: Có
A17: Datacall vật lý | B17: 9030605627 | C17: Sim vật lý | E17: Có
... A233: SB 50GB | B233: 9017166710 | C233: Sim sofbank 50G | E233: Có

Sheet 14_Sim_da_huy
A1: Nhóm | B1: Mã thiết bị (số sim) | C1: Khách hàng (lần hủy gần nhất) | D1: Mã DVKH | E1: Ngày hủy | F1: Đang ở sổ khác (không tính) | G1: Số lần hủy trong file
A2: Datacall esim | B2: 9052847246 | C2: CTV Hồng | D2: DV03393 | E2: 11/09/2026 | G2: 1
A3: Datacall esim | B3: 8025071647 | C3: CTV Hồng | D3: DV03392 | E3: 11/09/2026 | G3: 1
A4: Datacall esim | B4: 8024587843 | C4: CTV Hồng | D4: DV03391 | E4: 11/09/2026 | G4: 1
A5: Datacall esim | B5: 7044777209 | C5: CTV Hồng | D5: DV03390 | E5: 11/09/2026 | G5: 1
A6: Datacall esim | B6: 8088975466 | C6: CTV Hồng | D6: DV03389 | E6: 11/09/2026 | G6: 1
A7: Datacall esim | B7: 9054974897 | C7: CTV Hồng | D7: DV03388 | E7: 11/09/2026 | G7: 1
A8: Datacall esim | B8: 9073498992 | C8: CTV Hồng | D8: DV03387 | E8: 11/09/2026 | G8: 1
A9: Datacall esim | B9: 8024191372 | C9: CTV Hồng | D9: DV03386 | E9: 11/09/2026 | G9: 1
A10: Datacall esim | B10: 8095226528 | C10: CTV Hồng | D10: DV03385 | E10: 11/09/2026 | G10: 1
A11: Datacall esim | B11: 8095226927 | C11: CTV Hồng | D11: DV03384 | E11: 11/09/2026 | G11: 1
A12: Datacall esim | B12: 8017946952 | C12: CTV Hồng | D12: DV03383 | E12: 11/09/2026 | G12: 1
A13: Datacall esim | B13: 8022373674 | C13: CTV Hồng | D13: DV03382 | E13: 11/09/2026 | G13: 1
... A316: Datacall vật lý | B316: 09030608329 | C316: LoNg Ảnh (小島) | D316: DV00642 | E316: 30/09/2025 | G316: 1
A317: SB 100GB | B317: 7031436549 | C317: KH00301 Nguyễn Thanh Tĩnh | G317: 1
A318: SB 100GB | B318: 7031589208 | C318: KH00360 Nông Quang Duy | G318: 1
A319: SB 100GB | B319: 7031973979 | C319: KH00621 CTV Lê thủy | G319: 1
A320: SB 100GB | B320: 7031976184 | C320: KH00863 Việt Chanh Muối | G320: 1
A321: SB 100GB | B321: 8033438107 | C321: KH00355 kiếm hùng | G321: 1
A322: SB 100GB | B322: 8033539887 | C322: KH00356 KOL Cường | G322: 1
A323: SB 100GB | B323: 8035954269 | C323: KH00876 Đặng Viết | G323: 1
A324: SB 100GB | B324: 8035958193 | C324: KH00470 CTV Lương Trọng Thân | G324: 1
A325: SB 100GB | B325: 8035961803 | C325: Đại lý Tuấn BĐS | G325: 1
A326: SB 100GB | B326: 8035977675 | C326: KH00863 Quế Phương | G326: 1
A327: SB 100GB | B327: 8035982274 | C327: KH00863 Duy Khánh | G327: 1
A328: SB 100GB | B328: 8037383342 | C328: KH00385 CTV Hồng | G328: 1
... A593: Datacall vật lý | B593: 9089938532 | C593: KH00825 Dương Kim Vĩ | G593: 1
A594: SB 50GB | B594: 9017559242 | G594: 1
A595: SB 100GB | B595: 8037128220
A596: SB 100GB | B596: 8041206885
A597: SB 100GB | B597: 8045771850
A598: SB 100GB | B598: 8045793975
A599: SB 100GB | B599: 8045859547
A600: SB 100GB | B600: 8045859643
A601: SB 100GB | B601: 8045864081
A602: SB 100GB | B602: 8045864635
A603: SB 100GB | B603: 8045868357
A604: SB 100GB | B604: 8045872939
A605: SB 100GB | B605: 8045873166
A606: SB 50GB | B606: 7065711137
...

Sheet 15_Doi_tac_de_lai
A1: Nhóm | B1: Mã (số sim / IMEI) | C1: Ghi chú (người giữ | ghi chú | trạng thái sổ thu hồi cũ) | D1: Có trong DS nhập? | E1: Đang ở sổ khác (không tính)
A2: SB 100GB | B2: 9048661864 | C2: 3M-intel株式会社 荒井 清明 | sim đối tác để lại | D2: Có
A3: Datacall vật lý | B3: 7010553101 | C3: sim kuro dùng | sim đối tác để lại | D3: Có
A4: Datacall vật lý | B4: 8021480432 | C4: sim kuro dùng | sim đối tác để lại | D4: Có
A5: Datacall vật lý | B5: 8027934685 | C5: 3M-intel株式会社 荒井 清明 | sim đối tác để lại | D5: Có
A6: Datacall vật lý | B6: 9046559598 | C6: sim arai dùng | sim đối tác để lại | D6: Có
A7: Datacall vật lý | B7: 9050499284 | C7: sim kuro dùng | sim đối tác để lại | D7: Có
A8: Datacall vật lý | B8: 9058750833 | C8: 3M-intel株式会社 宮本 雄平 | sim đối tác để lại | D8: Có
A9: Datacall vật lý | B9: 9048422299 | C9: 3M dùng | D9: Có
A10: U20 | B10: 861720051172071 | C10: KT xác nhận 24/09 (file nhập ghi: C-cast dùng bên phía Miyamoto quản lý) | D10: Có
A11: U20 | B11: 861720051183797 | C11: KT xác nhận 24/09 (file nhập ghi: C-cast dùng bên phía Miyamoto quản lý) | D11: Có
A12: U20 | B12: 861720051152859 | C12: dùng tại văn phòng nhậtmiyamoto
A13: wimax | B13: 356221183715574 | C13: Arai đang dùng
A14: wimax | B14: 356221183572454 | C14: Arai đang dùng
A15: U20 | B15: 861720051173616 | C15: Đại lý Horizen
A16: U20 | B16: 861720051184357 | C16: Dùng tại văn phòng 3M Nhật
A17: Datacall vật lý | B17: 8088109191 | C17: Arai dùng từ tháng 9

Sheet 16_Xuat_dai_ly
A1: Nhóm | B1: Sản phẩm (gốc) | C1: Mã thiết bị | D1: Đại lý / Khách hàng | E1: Mã DVKH | F1: Trạng thái | G1: Ngày hủy | H1: Đang ở sổ khác (không tính) | I1: Số lần trong file | J1: Các mã DVKH
A2: U20 | B2: Wifi full dung lượng U20 | C2: 861720051155993 | D2: Công ty Teki - A Duân | E2: DV04038 | F2: Đã hủy | G2: 11/09/2026 | I2: 1 | J2: DV04038
A3: U20 | B3: Wifi full dung lượng U20 | C3: 861720051142892 | D3: Công ty Teki - A Duân | E3: DV04037 | F3: Đã hủy | G3: 11/09/2026 | I3: 1 | J3: DV04037
A4: U20 | B4: Wifi full dung lượng U20 | C4: 861720051180397 | D4: Công ty Teki - A Duân | E4: DV03128 | F4: Đã hủy | G4: 11/09/2026 | I4: 1 | J4: DV03128
A5: U20 | B5: Wifi full dung lượng U20 | C5: 861720051186998 | D5: Công ty Teki - A Duân | E5: DV03126 | F5: Đã hủy | G5: 11/09/2026 | I5: 1 | J5: DV03126
A6: U20 | B6: Wifi full dung lượng U20 | C6: 861720051141852 | D6: Công ty Teki - A Duân | E6: DV03124 | F6: Đã hủy | G6: 11/09/2026 | I6: 1 | J6: DV03124
A7: U20 | B7: Wifi full dung lượng U20 | C7: 861720051146018 | D7: Công ty Teki - A Duân | E7: DV03121 | F7: Đã hủy | G7: 11/09/2026 | I7: 1 | J7: DV03121
A8: U20 | B8: Wifi full dung lượng U20 | C8: 861720051158195 | D8: Đại lý Trưởng | E8: DV02802 | F8: Đã hủy | G8: 11/09/2026 | I8: 1 | J8: DV02802
A9: U20 | B9: Wifi full dung lượng U20 | C9: 861720051169879 | D9: Đại lý Trưởng | E9: DV02798 | F9: Đã hủy | G9: 11/09/2026 | I9: 1 | J9: DV02798
A10: U20 | B10: Wifi full dung lượng U20 | C10: 861720051186279 | D10: Công ty Teki - A Duân | E10: DV02713 | F10: Đã hủy | G10: 11/09/2026 | I10: 1 | J10: DV02713
A11: U20 | B11: Wifi full dung lượng U20 | C11: 861720051143098 | D11: Công ty Teki - A Duân | E11: DV02712 | F11: Đã hủy | G11: 11/09/2026 | I11: 1 | J11: DV02712
A12: U20 | B12: Wifi full dung lượng U20 | C12: 861720051142074 | D12: Công ty Teki - A Duân | E12: DV02709 | F12: Đã hủy | G12: 11/09/2026 | I12: 1 | J12: DV02709
A13: U20 | B13: Wifi full dung lượng U20 | C13: 861720051160993 | D13: Công ty Teki - A Duân | E13: DV02705 | F13: Đã hủy | G13: 11/09/2026 | I13: 1 | J13: DV02705
... A221: U3 | B221: Wifi full dung lượng U3 | C221: 869714043513684 | D221: Đại lý Trưởng | E221: DV00002 | F221: Đã hủy | G221: 31/07/2024 | I221: 1 | J221: DV00002

Sheet 17_Khong_thay_nhap_kho
A1: Nhóm | B1: Mã thiết bị | C1: Ghi chú | D1: Ghi chú trong file nhập | E1: Đang ở sổ khác (không tính)
A2: MR1 | B2: 355185373354703 | C2: Sổ cũ ghi ở kho nhưng kiểm kho không thấy (file KT 24/09)
A3: MR1 | B3: 355185373468966 | C3: Sổ cũ ghi ở kho nhưng kiểm kho không thấy (file KT 24/09)
A4: U20 | B4: 861720051135755 | C4: Sổ cũ ghi ở kho nhưng kiểm kho không thấy (file KT 24/09) | D4: Kho taka quản lý
A5: U20 | B5: 861720051138296 | C5: Sổ cũ ghi ở kho nhưng kiểm kho không thấy (file KT 24/09) | D5: Kho taka quản lý
A6: U20 | B6: 861720051143593 | C6: Sổ cũ ghi ở kho nhưng kiểm kho không thấy (file KT 24/09) | D6: Kho taka quản lý
A7: U20 | B7: 861720051153832 | C7: Sổ cũ ghi ở kho nhưng kiểm kho không thấy (file KT 24/09) | D7: Kho taka quản lý
A8: U20 | B8: 861720051161314 | C8: Sổ cũ ghi ở kho nhưng kiểm kho không thấy (file KT 24/09) | D8: Kho taka quản lý
A9: U20 | B9: 861720051166594 | C9: Sổ cũ ghi ở kho nhưng kiểm kho không thấy (file KT 24/09) | D9: Kho taka quản lý
A10: U20 | B10: 861720051180074 | C10: Sổ cũ ghi ở kho nhưng kiểm kho không thấy (file KT 24/09) | D10: Kho taka quản lý
A11: U20 | B11: 861720051182153 | C11: Sổ cũ ghi ở kho nhưng kiểm kho không thấy (file KT 24/09) | D11: Kho taka quản lý
A12: U20 | B12: 861720051188317 | C12: Sổ cũ ghi ở kho nhưng kiểm kho không thấy (file KT 24/09) | D12: Kho taka quản lý

Sheet 18_Hong_tra_NCC
A1: Nhóm | B1: Mã thiết bị | C1: Ghi chú | D1: Ghi chú trong file nhập | E1: Đang ở sổ khác (không tính)
A2: U20 | B2: 861720051194018 | C2: Trả lại nhà cung cấp - KT xác nhận 24/09 | D2: Kho taka quản lý
A3: U20 | B3: 861720051268705 | C3: Trả lại nhà cung cấp cùng sim 8025998197 (file DS sim trả lại NM) | D3: Kho taka quản lý
A4: WIMAX | B4: 356221183647306 | G4: KT 24/09: chuyển từ Bán đứt sang Cần thu hồi - PM ghi đã xuất cho khách - bán đứt - hết dùng chờ | J4: KT bổ sung 24/09
A5: U20 | B5: 861720051173137 | C5: Đem đi làm hợp quy L1
A6: U20 | B6: 861720051186758 | C6: Đem đi làm hợp quy L1
A7: U20 | B7: 861720051189331 | C7: Đem đi làm hợp quy L1
A8: U20 | B8: 861720051190552 | C8: Thất lạc ở kho ibaraki quản lý
A9: U20 | B9: 861720051170398 | C9: Thất lạc ở kho ibaraki quản lý
A10: U20 | B10: 861720051142033 | C10: cục hỏng khách đã đền tiền
A11: U20 | B11: 861720051174275 | C11: Khách làm hỏng, đã đền tiền
