Workbook

Sheet Tổng hợp
A1: BÁO CÁO TIỀN THU VỀ TÀI KHOẢN THÁNG 7.2026/Collections received in July
A2: TÀI KHOẢN NHẬN Bank account | B2: THU HỘ KHÁCH WIFI CỐ ĐỊNH CỦA ĐẠI LÝ Collect fixed Wi-Fi payments from the agent’s customers | D2: WIFI CẦM TAY | H2: Other | I2: Chưa xác định/Not yet determined | J2: TỔNG/ TOTAL
B3: Cọc/ Deposit | C3: Cước/Monthly fee | D3: Khách sử dụng từ tháng 7 Customer has been using it since July. | F3: Khách sử dụng trước tháng 7 Customer used it before July
D4: Cọc/ Deposit | E4: Cước/ Monthly fee | F4: Cọc/ Deposit | G4: Cước/ Monthly fee
A5: GMO | B5: =SUMIFS(GMO!G:G,GMO!E:E,"Wifi cố định") -> 48451 | C5: =SUMIFS(GMO!H:H,GMO!E:E,"Wifi cố định") -> 540352
A6: Yucho Arai | B6: =SUMIFS('Yucho Arai'!H:H,'Yucho Arai'!F:F,"Cố định") -> 754789 | C6: =SUMIFS('Yucho Arai'!I:I,'Yucho Arai'!F:F,"Cố định") -> 15761
A7: SBI
A8: Arai 7121 | C8: =SUMIF('Arai 7121'!G:G,"cố định",'Arai 7121'!B:B) -> 123300
A9: TỔNG | B9: =SUM(B5:B8) -> 803240 | C9: =SUM(C5:C8) -> 679413
A10: Tiền cần trả cho đại lý | C10: =+C9 -> 679413

Sheet Tổng hợp tiền thu theo mã U
D1: STT | E1: ID | F1: CỌC | G1: CƯỚC | H1: TOTAL
F2: =SUBTOTAL(9,F3:F1000) -> 803240 | G2: =SUBTOTAL(9,G3:G1000) -> 679413 | H2: =SUBTOTAL(9,H3:H1000) -> 1482653
D3: 1 | E3: U00003129596 | F3: =SUMIF('Yucho Arai'!N:N,'Tổng hợp tiền thu theo mã U'!E3,'Yucho Arai'!H:H)+SUMIF(GMO!I:I,'Tổng hợp tiền thu theo mã U'!E3,GMO!G:G) -> 6850 | G3: =SUMIF('Yucho Arai'!N:N,'Tổng hợp tiền thu theo mã U'!E3,'Yucho Arai'!I:I)+SUMIF(GMO!I:I,'Tổng hợp tiền thu theo mã U'!E3,GMO!H:H)+SUMIF('Arai 7121'!H:H,'Tổng hợp tiền thu theo mã U'!E3,'Arai 7121'!B:B) -> 0 | H3: =G3+F3 -> 6850
D4: 2 | E4: U00007891899 | F4: =SUMIF('Yucho Arai'!N:N,'Tổng hợp tiền thu theo mã U'!E4,'Yucho Arai'!H:H)+SUMIF(GMO!I:I,'Tổng hợp tiền thu theo mã U'!E4,GMO!G:G) -> 6850 | G4: =SUMIF('Yucho Arai'!N:N,'Tổng hợp tiền thu theo mã U'!E4,'Yucho Arai'!I:I)+SUMIF(GMO!I:I,'Tổng hợp tiền thu theo mã U'!E4,GMO!H:H)+SUMIF('Arai 7121'!H:H,'Tổng hợp tiền thu theo mã U'!E4,'Arai 7121'!B:B) -> 0 | H4: =G4+F4 -> 6850
D5: 3 | E5: U00003130103 | F5: =SUMIF('Yucho Arai'!N:N,'Tổng hợp tiền thu theo mã U'!E5,'Yucho Arai'!H:H)+SUMIF(GMO!I:I,'Tổng hợp tiền thu theo mã U'!E5,GMO!G:G) -> 4290 | G5: =SUMIF('Yucho Arai'!N:N,'Tổng hợp tiền thu theo mã U'!E5,'Yucho Arai'!I:I)+SUMIF(GMO!I:I,'Tổng hợp tiền thu theo mã U'!E5,GMO!H:H)+SUMIF('Arai 7121'!H:H,'Tổng hợp tiền thu theo mã U'!E5,'Arai 7121'!B:B) -> 0 | H5: =G5+F5 -> 4290
D6: 4 | E6: U00007882257 | F6: =SUMIF('Yucho Arai'!N:N,'Tổng hợp tiền thu theo mã U'!E6,'Yucho Arai'!H:H)+SUMIF(GMO!I:I,'Tổng hợp tiền thu theo mã U'!E6,GMO!G:G) -> 4297 | G6: =SUMIF('Yucho Arai'!N:N,'Tổng hợp tiền thu theo mã U'!E6,'Yucho Arai'!I:I)+SUMIF(GMO!I:I,'Tổng hợp tiền thu theo mã U'!E6,GMO!H:H)+SUMIF('Arai 7121'!H:H,'Tổng hợp tiền thu theo mã U'!E6,'Arai 7121'!B:B) -> 0 | H6: =G6+F6 -> 4297
D7: 5 | E7: U00007885485 | F7: =SUMIF('Yucho Arai'!N:N,'Tổng hợp tiền thu theo mã U'!E7,'Yucho Arai'!H:H)+SUMIF(GMO!I:I,'Tổng hợp tiền thu theo mã U'!E7,GMO!G:G) -> 3297 | G7: =SUMIF('Yucho Arai'!N:N,'Tổng hợp tiền thu theo mã U'!E7,'Yucho Arai'!I:I)+SUMIF(GMO!I:I,'Tổng hợp tiền thu theo mã U'!E7,GMO!H:H)+SUMIF('Arai 7121'!H:H,'Tổng hợp tiền thu theo mã U'!E7,'Arai 7121'!B:B) -> 0 | H7: =G7+F7 -> 3297
D8: 6 | E8: U00003130098 | F8: =SUMIF('Yucho Arai'!N:N,'Tổng hợp tiền thu theo mã U'!E8,'Yucho Arai'!H:H)+SUMIF(GMO!I:I,'Tổng hợp tiền thu theo mã U'!E8,GMO!G:G) -> 3000 | G8: =SUMIF('Yucho Arai'!N:N,'Tổng hợp tiền thu theo mã U'!E8,'Yucho Arai'!I:I)+SUMIF(GMO!I:I,'Tổng hợp tiền thu theo mã U'!E8,GMO!H:H)+SUMIF('Arai 7121'!H:H,'Tổng hợp tiền thu theo mã U'!E8,'Arai 7121'!B:B) -> 297 | H8: =G8+F8 -> 3297
D9: 7 | E9: U00007884021 | F9: =SUMIF('Yucho Arai'!N:N,'Tổng hợp tiền thu theo mã U'!E9,'Yucho Arai'!H:H)+SUMIF(GMO!I:I,'Tổng hợp tiền thu theo mã U'!E9,GMO!G:G) -> 4000 | G9: =SUMIF('Yucho Arai'!N:N,'Tổng hợp tiền thu theo mã U'!E9,'Yucho Arai'!I:I)+SUMIF(GMO!I:I,'Tổng hợp tiền thu theo mã U'!E9,GMO!H:H)+SUMIF('Arai 7121'!H:H,'Tổng hợp tiền thu theo mã U'!E9,'Arai 7121'!B:B) -> 290 | H9: =G9+F9 -> 4290
D10: 8 | E10: U00007885523 | F10: =SUMIF('Yucho Arai'!N:N,'Tổng hợp tiền thu theo mã U'!E10,'Yucho Arai'!H:H)+SUMIF(GMO!I:I,'Tổng hợp tiền thu theo mã U'!E10,GMO!G:G) -> 2797 | G10: =SUMIF('Yucho Arai'!N:N,'Tổng hợp tiền thu theo mã U'!E10,'Yucho Arai'!I:I)+SUMIF(GMO!I:I,'Tổng hợp tiền thu theo mã U'!E10,GMO!H:H)+SUMIF('Arai 7121'!H:H,'Tổng hợp tiền thu theo mã U'!E10,'Arai 7121'!B:B) -> 0 | H10: =G10+F10 -> 2797
D11: 9 | E11: U00007872681 | F11: =SUMIF('Yucho Arai'!N:N,'Tổng hợp tiền thu theo mã U'!E11,'Yucho Arai'!H:H)+SUMIF(GMO!I:I,'Tổng hợp tiền thu theo mã U'!E11,GMO!G:G) -> 3000 | G11: =SUMIF('Yucho Arai'!N:N,'Tổng hợp tiền thu theo mã U'!E11,'Yucho Arai'!I:I)+SUMIF(GMO!I:I,'Tổng hợp tiền thu theo mã U'!E11,GMO!H:H)+SUMIF('Arai 7121'!H:H,'Tổng hợp tiền thu theo mã U'!E11,'Arai 7121'!B:B) -> 290 | H11: =G11+F11 -> 3290
D12: 10 | E12: U00007885536 | F12: =SUMIF('Yucho Arai'!N:N,'Tổng hợp tiền thu theo mã U'!E12,'Yucho Arai'!H:H)+SUMIF(GMO!I:I,'Tổng hợp tiền thu theo mã U'!E12,GMO!G:G) -> 3297 | G12: =SUMIF('Yucho Arai'!N:N,'Tổng hợp tiền thu theo mã U'!E12,'Yucho Arai'!I:I)+SUMIF(GMO!I:I,'Tổng hợp tiền thu theo mã U'!E12,GMO!H:H)+SUMIF('Arai 7121'!H:H,'Tổng hợp tiền thu theo mã U'!E12,'Arai 7121'!B:B) -> 0 | H12: =G12+F12 -> 3297
D13: 11 | E13: U00003130101 | F13: =SUMIF('Yucho Arai'!N:N,'Tổng hợp tiền thu theo mã U'!E13,'Yucho Arai'!H:H)+SUMIF(GMO!I:I,'Tổng hợp tiền thu theo mã U'!E13,GMO!G:G) -> 3297 | G13: =SUMIF('Yucho Arai'!N:N,'Tổng hợp tiền thu theo mã U'!E13,'Yucho Arai'!I:I)+SUMIF(GMO!I:I,'Tổng hợp tiền thu theo mã U'!E13,GMO!H:H)+SUMIF('Arai 7121'!H:H,'Tổng hợp tiền thu theo mã U'!E13,'Arai 7121'!B:B) -> 0 | H13: =G13+F13 -> 3297
D14: 12 | E14: U00007885516 | F14: =SUMIF('Yucho Arai'!N:N,'Tổng hợp tiền thu theo mã U'!E14,'Yucho Arai'!H:H)+SUMIF(GMO!I:I,'Tổng hợp tiền thu theo mã U'!E14,GMO!G:G) -> 6594 | G14: =SUMIF('Yucho Arai'!N:N,'Tổng hợp tiền thu theo mã U'!E14,'Yucho Arai'!I:I)+SUMIF(GMO!I:I,'Tổng hợp tiền thu theo mã U'!E14,GMO!H:H)+SUMIF('Arai 7121'!H:H,'Tổng hợp tiền thu theo mã U'!E14,'Arai 7121'!B:B) -> 0 | H14: =G14+F14 -> 6594
... D465: 462 | E465: U00007883086 | F465: =SUMIF('Yucho Arai'!N:N,'Tổng hợp tiền thu theo mã U'!E465,'Yucho Arai'!H:H)+SUMIF(GMO!I:I,'Tổng hợp tiền thu theo mã U'!E465,GMO!G:G) -> 0 | G465: =SUMIF('Yucho Arai'!N:N,'Tổng hợp tiền thu theo mã U'!E465,'Yucho Arai'!I:I)+SUMIF(GMO!I:I,'Tổng hợp tiền thu theo mã U'!E465,GMO!H:H)+SUMIF('Arai 7121'!H:H,'Tổng hợp tiền thu theo mã U'!E465,'Arai 7121'!B:B) -> 5000 | H465: =G465+F465 -> 5000

Sheet Báo cáo cọc
A1: BÁO CÁO TIỀN CỌC HẾT THÁNG 8 | H1: NOTE
A2: 1 | B2: Tiền cọc tính đến hết tháng 6 | C2: Total customer deposit balance as of the end of January | E2: 5677256
A3: 2 | B3: Doanh thu tháng 7 | C3: Total sales received in February, broken down by account (Yucho / SBI / GMO) | D3: Yucho | E3: ='Tổng hợp'!G6 -> 0
D4: SBI | E4: ='Tổng hợp'!G7 -> 0
D5: GMO | E5: ='Tổng hợp'!G5 -> 0
A6: 3 | B6: Cọc tháng 7 | C6: Total customer deposits collected in February, broken down by account (Yucho / SBI / GMO) | D6: Yucho | E6: ='Tổng hợp'!B6+'Tổng hợp'!D6+'Tổng hợp'!F6 -> 754789
D7: SBI
D8: GMO | E8: ='Tổng hợp'!B5+'Tổng hợp'!D5+'Tổng hợp'!F5 -> 48451
A9: 4 | B9: Tiền hoàn cọc tháng 7 | C9: Total customer deposit refunds made in February
A10: 5 | B10: Tiền cọc chuyển thành doanh thu trong tháng 7 | C10: Total amount of previously held customer deposits that were recognized as sales during February
A11: 6 | B11: Tiền cọc tính đến hết tháng 7 | C11: Total customer deposit balance as of the end of February | E11: =E2+E6-E9-E10+E8 -> 6480496
A12: 7 | B12: Các phần khác về thu tiền | C12: Any other notable items regarding sales receipts or refunds | D12: Yucho | E12: ='Tổng hợp'!I6+'Tổng hợp'!H6+'Tổng hợp'!E6+'Tổng hợp'!C6 -> 15761 | H12: Gồm các khoản khác và không rõ, tiền cước của các khách mới từ tháng 7+8
D13: SBI | E13: ='Tổng hợp'!H7 -> 0 | H13: Gồm các khoản luân chuyển, Hoa hồng Sonet, phí vận chuyển được hoàn về
D14: GMO | E14: ='Tổng hợp'!I5+'Tổng hợp'!H5+'Tổng hợp'!E5+'Tổng hợp'!C5 -> 540352 | H14: Tiền wifi cố định đại lý chuyển nhờ

Sheet Yucho Arai
A1: ĐƠN VỊ | B1: NGÀY THÁNG | C1: MÃ KHÁCH HÀNG | D1: TÊN KHÁCH HÀNG | F1: LOẠI DỊCH VỤ | G1: THU | H1: CỌC | I1: CƯỚC | J1: KHÁC/KHÔNG RÕ | K1: CHI | N1: Mã U (NTT)
G2: =SUBTOTAL(9,G3:G10000) -> 770550 | H2: =SUBTOTAL(9,H3:H10000) -> 754789 | I2: =SUBTOTAL(9,I3:I10000) -> 15761 | J2: =SUBTOTAL(9,J3:J10000) -> 0 | K2: =SUBTOTAL(9,K3:K10000) -> 0
A3: ĐLý tecno | B3: 46235 | C3: KH02322 | D3: Đại lý Kiên- Luân JP | F3: Cố định | G3: 6850 | H3: 6850 | I3: 0 | J3: 0 | M3: Đơn mới | N3: U00003129596 | O3: 20260801 | P3: 202608010000001 | Q3: 6850 | S3: 送金 | T3: ＮＧＵＹＥＮ Ｖ | U3: 241.647
A4: Công ty | B4: 46235 | C4: KH01097 | D4: Hoàng Sơn | F4: Cầm tay | G4: 7700 | I4: 7700 | J4: 0 | M4: Khách cũ | O4: 20260801 | P4: 202608010000002 | Q4: 7700 | S4: 送金 | T4: ＤＵＯＮＧ ＶＡ | U4: 249.347
A5: ĐLý tecno | B5: 46235 | C5: KH02600 | D5: Đại lý AKIKO | F5: Cố định | G5: 6850 | H5: 6850 | I5: 0 | J5: 0 | M5: Đơn mới | N5: U00007891899 | O5: 20260801 | P5: 202608010000003 | Q5: 6850 | S5: 送金 | T5: ＴＨＡＣＨ ＴＨ | U5: 256.197
A6: Công ty | B6: 46235 | C6: KH01155 | D6: Thu Cúc | F6: Cầm tay | G6: 2475 | I6: 2475 | J6: 0 | M6: Khách cũ | O6: 20260801 | P6: 202608010000004 | Q6: 2475 | S6: 送金 | T6: ＴＲＡＮ ＴＨＩ | U6: 258.672
A7: Công ty | B7: 46235 | C7: KH01145 | D7: Hoangtrung Nguyen | F7: Cầm tay | G7: 3850 | I7: 3850 | J7: 0 | M7: Khách cũ | O7: 20260801 | P7: 202608010000005 | Q7: 3850 | S7: 送金 | T7: ＮＧＵＹＥＮ Ｓ | U7: 262.522
A8: ĐLý Hoàng | B8: 46235 | C8: KH03517 | D8: Takahashi Maricel Hallig | F8: Cố định | G8: 493 | H8: 493 | I8: 0 | J8: 0 | M8: Đơn mới | N8: U00003130103 | O8: 20260801 | P8: 202608010000006 | Q8: 493 | S8: 送金 | T8: ＴＡＫＡＨＡＳＨ | U8: 263.015
A9: ĐLý Hoàng | B9: 46235 | C9: KH00498 | D9: Đỗ Phong | F9: Cầm tay | G9: 500 | H9: 500 | I9: 0 | J9: 0 | M9: Đơn mới | O9: 20260801 | P9: 202608010000007 | Q9: 500 | S9: 送金 | T9: ＬＥ ＴＨＩ Ｓ | U9: 263.515
A10: ĐLý Việt | B10: 46236 | C10: KH03511 | D10: Osep Rosete | F10: Cố định | G10: 500 | H10: 500 | I10: 0 | J10: 0 | M10: Đơn mới | N10: U00007882257 | O10: 20260802 | P10: 202608020000001 | Q10: 500 | S10: 送金 | T10: ＳＡＮＣＨＥＺ | U10: 264.015
A11: Công ty | B11: 46236 | C11: KH02748 | D11: Pyaephyo Kyaw | F11: Cầm tay | G11: 3850 | I11: 3850 | J11: 0 | M11: Khách cũ | O11: 20260802 | P11: 202608020000002 | Q11: 3850 | S11: 送金 | T11: ＰＹＡＥ ＰＨＹ | U11: 267.865
A12: Công ty | B12: 46236 | C12: KH00926 | D12: Nhung Min's | F12: Cầm tay | G12: 46200 | I12: 46200 | J12: 0 | M12: Khách cũ | O12: 20260802 | P12: 202608020000003 | Q12: 46200 | S12: 送金 | T12: ＬＵＯＮＧ ＶＡ | U12: 314.065
A13: ĐLý Hoàng | B13: 46237 | C13: KH03356 | D13: Kewal Ghimire | F13: Cầm tay | G13: 6647 | H13: 3000 | I13: 3647 | J13: 0 | M13: Đơn mới | O13: 20260803 | P13: 202608030000001 | Q13: 6647 | S13: 送金 | T13: 81961912863ﾆﾂ | U13: 320.712
A14: ĐLý Hoàng | B14: 46237 | C14: KH03366 | D14: オランデ ラケル | F14: Cố định | G14: 4290 | H14: 4000 | I14: 290 | J14: 0 | M14: Đơn mới | N14: U00007889069 | O14: 20260803 | P14: 202608030000002 | Q14: 4290 | S14: 送金 | T14: 81961912631ﾆﾂ | U14: 325.002
A15: ĐLý Việt | B15: 46237 | C15: KH03440 | D15: Dreads Shevo | F15: Cố định | G15: 3297 | H15: 3000 | I15: 297 | J15: 0 | M15: Đơn mới | N15: U00003130098 | O15: 20260803 | P15: 202608030000003 | Q15: 3297 | S15: 送金 | T15: 81961912955ﾆﾂ | U15: 328.299
A16: ĐLý Hoàng | B16: 46237 | C16: KH03367 | D16: Mamoouroii Diouf | F16: Cố định | G16: 4290 | H16: 4000 | I16: 290 | J16: 0 | M16: Đơn mới | N16: U00007884021 | O16: 20260803 | P16: 202608030000004 | Q16: 4290 | S16: 送金 | T16: 81961912642ﾆﾂ | U16: 332.589
A17: ĐLý Hoàng | B17: 46237 | C17: KH03411 | D17: Shima Jorge | F17: Cầm tay | G17: 7140 | H17: 3000 | I17: 4140 | J17: 0 | M17: Đơn mới | O17: 20260803 | P17: 202608030000005 | Q17: 7140 | S17: 送金 | T17: 81961912885ﾆﾂ | U17: 339.729
A18: ĐLý Hoàng | B18: 46237 | C18: KH03392 | D18: Junglen Villanueva | F18: Cầm tay | G18: 8290 | H18: 4000 | I18: 4290 | J18: 0 | M18: Đơn mới | O18: 20260803 | P18: 202608030000006 | Q18: 8290 | S18: 送金 | T18: 81961912701ﾆﾂ | U18: 348.019
A19: ĐLý Việt | B19: 46237 | C19: KH03446 | D19: Ferndo Acero | F19: Cầm tay | G19: 6597 | H19: 4000 | I19: 2597 | J19: 0 | M19: Đơn mới | O19: 20260803 | P19: 202608030000007 | Q19: 6597 | S19: 送金 | T19: 81961912826ﾆﾂ | U19: 354.616
A20: ĐLý Hoàng | B20: 46237 | C20: KH03469 | D20: Ly Chinh | F20: Cầm tay | G20: 7092 | H20: 4000 | I20: 3092 | J20: 0 | M20: Đơn mới | O20: 20260803 | P20: 202608030000008 | Q20: 7092 | S20: 送金 | T20: 81961912900ﾆﾂ | U20: 361.708
A21: ĐLý Việt | B21: 46237 | C21: KH03451 | D21: Dang Vizcarra- de Leon | F21: Cố định | G21: 2797 | H21: 2797 | I21: 0 | J21: 0 | M21: Đơn mới | N21: U00007885523 | O21: 20260803 | P21: 202608030000009 | Q21: 2797 | S21: 送金 | T21: 81961912981ﾆﾂ | U21: 364.505
A22: ĐLý Hoàng | B22: 46237 | C22: KH03430 | D22: Whitney Guimare | F22: Cầm tay | G22: 7140 | H22: 3000 | I22: 4140 | J22: 0 | M22: Đơn mới | O22: 20260803 | P22: 202608030000010 | Q22: 7140 | S22: 送金 | T22: 81961912771ﾆﾂ | U22: 371.645
A23: ĐLý Việt | B23: 46237 | C23: KH03416 | D23: Eduardo Fujiki | F23: Cố định | G23: 3290 | H23: 3000 | I23: 290 | J23: 0 | M23: Đơn mới | N23: U00007872681 | O23: 20260803 | P23: 202608030000011 | Q23: 3290 | S23: 送金 | T23: 81961912911ﾆﾂ | U23: 374.935
A24: ĐLý Hoàng | B24: 46237 | C24: KH03490 | D24: Rosalie Castalone | F24: Cầm tay | G24: 6090 | H24: 3000 | I24: 3090 | J24: 0 | M24: Đơn mới | O24: 20260803 | P24: 202608030000012 | Q24: 6090 | S24: 送金 | T24: 81961913191ﾆﾂ | U24: 381.025
A25: ĐLý Việt | B25: 46237 | C25: KH03458 | D25: Ar Kar | F25: Cố định | G25: 3297 | H25: 3297 | I25: 0 | J25: 0 | M25: Đơn mới | N25: U00007885485 | O25: 20260803 | P25: 202608030000013 | Q25: 3297 | S25: 送金 | T25: 81961912944ﾆﾂ | U25: 384.322
A26: ĐLý Hoàng | B26: 46237 | C26: KH03381 | D26: Michelle Mekz | F26: Cố định | G26: 4290 | H26: 4000 | I26: 290 | J26: 0 | M26: Đơn mới | N26: U00007892020 | O26: 20260803 | P26: 202608030000014 | Q26: 4290 | S26: 送金 | T26: 81961913062ﾆﾂ | U26: 388.612
A27: ĐLý Việt | B27: 46237 | C27: KH03397 | D27: Dumindu J Rajapaksha | F27: Cố định | G27: 3297 | H27: 3297 | I27: 0 | J27: 0 | M27: Đơn mới | N27: U00003130101 | O27: 20260803 | P27: 202608030000015 | Q27: 3297 | S27: 送金 | T27: 81961912966ﾆﾂ | U27: 391.909
A28: ĐLý Việt | B28: 46237 | C28: KH03473 | D28: Juka Sasaki | F28: Cố định | G28: 3297 | H28: 3297 | I28: 0 | J28: 0 | M28: Đơn mới | N28: U00007885516 | O28: 20260803 | P28: 202608030000016 | Q28: 3297 | S28: 送金 | T28: 81961913003ﾆﾂ | U28: 395.206
A29: ĐLý Hoàng | B29: 46237 | C29: KH03485 | D29: Muhammed Sahal | F29: Cầm tay | G29: 5250 | H29: 3000 | I29: 2250 | J29: 0 | M29: Đơn mới | O29: 20260803 | P29: 202608030000017 | Q29: 5250 | S29: 送金 | T29: 81961913036ﾆﾂ | U29: 400.456
A30: ĐLý Hoàng | B30: 46237 | C30: KH03449 | D30: Vandam Sato | F30: Cầm tay | G30: 8290 | H30: 4000 | I30: 4290 | J30: 0 | M30: Đơn mới | O30: 20260803 | P30: 202608030000018 | Q30: 8290 | S30: 送金 | T30: 81961912815ﾆﾂ | U30: 408.746
A31: ĐLý tecno | B31: 46237 | C31: KH02600 | D31: Đại lý AKIKO | F31: Cố định | G31: 6850 | H31: 6850 | I31: 0 | J31: 0 | M31: Đơn mới | N31: U00007892018 | O31: 20260803 | P31: 202608030000019 | Q31: 6850 | S31: 送金 | T31: ＴＲＩＮＨ ＤＡ | U31: 415.596
A32: ĐLý Việt | B32: 46237 | C32: KH03525 | D32: Kaung Myat San | F32: Cầm tay | G32: 493 | H32: 493 | I32: 0 | J32: 0 | M32: Đơn mới | O32: 20260803 | P32: 202608030000020 | Q32: 493 | S32: ことら | T32: ｶｳﾝ ﾐﾔﾂ ｻﾝ | U32: 416.089
A33: ĐLý Hoàng | B33: 46237 | C33: KH03533 | D33: Phạm Bá Manh | F33: Cố định | G33: 4000 | H33: 4000 | I33: 0 | J33: 0 | M33: Đơn mới | N33: U00007883738 | O33: 20260803 | P33: 202608030000021 | Q33: 4000 | S33: 送金 | T33: ＰＨＡＭ ＢＡ | U33: 420.089
A34: Công ty | B34: 46237 | C34: KH01456 | D34: Trần Thị Đào | F34: Cầm tay | G34: 3850 | I34: 3850 | J34: 0 | M34: Khách cũ | O34: 20260803 | P34: 202608030000022 | Q34: 3850 | S34: 送金 | T34: ＴＲＡＮ ＴＨＩ | U34: 423.939
A35: ĐLý tecno | B35: 46237 | C35: KH02600 | D35: Đại lý AKIKO | F35: Cố định | G35: 6850 | H35: 6850 | I35: 0 | J35: 0 | M35: Đơn mới | N35: U00007891917 | O35: 20260803 | P35: 202608030000023 | Q35: 6850 | S35: 送金 | T35: ＮＧＵＹＥＮ Ｔ | U35: 430.789
A36: đại lý Hoa | B36: 46237 | C36: KH00419 | D36: Nguyễn Chi | F36: Cầm tay | G36: 2153 | I36: 2153 | J36: 0 | M36: Đơn mới | O36: 20260803 | P36: 202608030000024 | Q36: 2153 | S36: 送金 | T36: ＮＧＵＹＥＮ Ｔ | U36: 432.942
A37: ĐLý tecno | B37: 46237 | C37: KH02271 | D37: Đại Lý Kiên- Sơn Tùng | F37: Cố định | G37: 7000 | H37: 7000 | I37: 0 | J37: 0 | M37: Đơn mới | N37: U00007889274 | O37: 20260803 | P37: 202608030000025 | Q37: 7000 | S37: 送金 | T37: ＮＧＵＹＥＮ Ｖ | U37: 439.942
A38: ĐLý Hoàng | B38: 46238 | C38: KH03379 | D38: Mab Aguilar Betz | F38: Cầm tay | G38: 5985 | H38: 3000 | I38: 2985 | J38: 0 | M38: Đơn mới | O38: 20260804 | P38: 202608040000001 | Q38: 5985 | S38: 送金 | T38: 81961913025ﾆﾂ | U38: 445.927
A39: ĐLý Hoàng | B39: 46238 | C39: KH02378 | D39: Avenilda Liwacat | F39: Cầm tay | G39: 5252 | H39: 3000 | I39: 2252 | J39: 0 | M39: Đơn mới | O39: 20260804 | P39: 202608040000002 | Q39: 5252 | S39: 送金 | T39: 81961912896ﾆﾂ | U39: 451.179
A40: ĐLý Việt | B40: 46238 | C40: KH03482 | D40: Nang Hsi Ying | F40: Cầm tay | G40: 5252 | H40: 3000 | I40: 2252 | J40: 0 | M40: Đơn mới | O40: 20260804 | P40: 202608040000003 | Q40: 5252 | S40: 送金 | T40: 81961913073ﾆﾂ | U40: 456.431
...

Sheet GMO
A1: ĐƠN VỊ | B1: DATE | C1: MÃ KHÁCH HÀNG | D1: TÊN KHÁCH HÀNG | E1: LOẠI DỊCH VỤ | F1: THU | G1: CỌC | H1: CƯỚC | I1: Mã U (NTT) | J1: MÃ GIAO DỊCH
F2: =SUBTOTAL(9,F3:F10000) -> 588803 | G2: =SUBTOTAL(9,G3:G10000) -> 48451 | H2: =SUBTOTAL(9,H3:H10000) -> 540352
A3: Công ty | B3: 46235 | C3: KH02569 | D3: Arshad Mehmood Bhatti | E3: Wifi cố định | F3: 2000 | H3: 2000 | I3: U00007855001 | J3: 1785115561423
A4: ĐLý Hoàng | B4: 46235 | C4: KH03369 | D4: Shabba Meek | E4: Wifi cố định | F4: 2000 | H4: 2000 | I4: U00007843013 | J4: 1785396146511
A5: Công ty | B5: 46235 | C5: KH00349 | D5: Nguyễn Văn Sang | E5: Wifi cố định | F5: 2000 | H5: 2000 | I5: U00007817327 | J5: 1785392650438
A6: Công ty | B6: 46235 | C6: KH01672 | D6: Siyaan Jubiyana | E6: Wifi cầm tay | F6: 3850 | H6: 3850 | J6: 1785546677369
A7: Công ty | B7: 46235 | C7: KH02669 | D7: Na Na | E7: Wifi cố định | F7: 3000 | H7: 3000 | I7: U00007850869 | J7: 1785373882254
A8: ĐLý Hoàng | B8: 46235 | C8: KH03481 | D8: Joebert bringas Imperial | E8: Wifi cầm tay | F8: 8000 | G8: 4000 | H8: 4000 | J8: 1785460890609
A9: Công ty | B9: 46235 | C9: KH03083 | D9: Sally Myat | E9: Wifi cố định | F9: 2000 | H9: 2000 | I9: U00007850382 | J9: 1785512384054
A10: ĐLý Hoàng | B10: 46235 | C10: KH03380 | D10: モット モット | E10: Wifi cầm tay | F10: 5695 | G10: 3000 | H10: 2695 | J10: 1785495792228
A11: ĐLý Việt | B11: 46235 | C11: KH01841 | D11: Jahidul Islam | E11: Wifi cầm tay | F11: 7616 | H11: 7616 | J11: 1785554189437
A12: ĐLý Việt | B12: 46235 | C12: KH03504 | D12: Sandra Liliana Hernández | E12: Wifi cố định | F12: 500 | G12: 500 | I12: U00007892393 | J12: 1785559423378
A13: Công ty | B13: 46235 | C13: KH02469 | D13: Sandesh Rai | E13: Wifi cố định | F13: 2000 | H13: 2000 | I13: U00007835165 | J13: 1785304592709
A14: Công ty | B14: 46235 | C14: KH02966 | D14: Rosalie kato | E14: Wifi cố định | F14: 2000 | H14: 2000 | I14: U00007803797 | J14: 1784958614699
A15: Công ty | B15: 46235 | C15: KH01908 | D15: Cornelius Z. Yoko II | E15: Wifi cố định | F15: 2000 | H15: 2000 | I15: U00007855255 | J15: 1784859962080
A16: Công ty | B16: 46235 | C16: KH02543 | D16: Asam Ahamed | E16: Wifi cố định | F16: 2000 | H16: 2000 | I16: U00007803481 | J16: 1785063481184
A17: ĐLý Việt | B17: 46235 | C17: KH03491 | D17: Arisa Sasaki | E17: Wifi cố định | F17: 500 | G17: 500 | I17: U00007892396 | J17: 1785479596947
A18: ĐLý Hoàng | B18: 46235 | C18: KH03509 | D18: エリカ マリー マイカ | E18: Wifi cầm tay | F18: 493 | H18: 493 | J18: 1785579762217
A19: Công ty | B19: 46235 | C19: KH02441 | D19: Mohamed Anas | E19: Wifi cố định | F19: 2000 | H19: 2000 | I19: U00007871416 | J19: 1785121344444
A20: Công ty | B20: 46235 | C20: KH01880 | D20: Md Shahadat Hossain | E20: Wifi cầm tay | F20: 3850 | H20: 3850 | J20: 1785505762025
A21: ĐLý Hoàng | B21: 46235 | C21: KH03475 | D21: Enriquez Ynnej | E21: Wifi cố định | F21: 2000 | H21: 2000 | I21: U00007804022 | J21: 1785581747932
A22: Công ty | B22: 46235 | C22: KH02237 | D22: Rey Villaver | E22: Wifi cầm tay | F22: 3850 | H22: 3850 | J22: 1785555041516
A23: Công ty | B23: 46235 | C23: KH02134 | D23: Petit Willy | E23: Wifi cố định | F23: 2000 | H23: 2000 | I23: U00007811162 | J23: 1784905956032
A24: Công ty | B24: 46236 | C24: KH02542 | D24: Yumi V. Ogue | E24: Wifi cố định | F24: 2000 | H24: 2000 | I24: U00007819758 | J24: 1784883948457
A25: Công ty | B25: 46236 | C25: KH02205 | D25: Lablab Alexandra | E25: Wifi cố định | F25: 2000 | H25: 2000 | I25: U00007857297 | J25: 1785119355590
A26: Công ty | B26: 46236 | C26: KH02125 | D26: 斎斎 | E26: Wifi cố định | F26: 2000 | H26: 2000 | I26: U00007847235 | J26: 1784983146902
A27: Công ty | B27: 46236 | C27: KH02520 | D27: Bebelyn Okazaki | E27: Wifi cố định | F27: 2000 | H27: 2000 | I27: U00007802607 | J27: 1785550913498
A28: ĐLý Hoàng | B28: 46236 | C28: KH03422 | D28: An Is | E28: Wifi cố định | F28: 2000 | H28: 2000 | I28: U00007794721 | J28: 1785380301800
A29: Công ty | B29: 46236 | C29: KH01964 | D29: Ilham Taka | E29: Wifi cầm tay | F29: 4200 | H29: 4200 | J29: 1785637917320
A30: ĐLý Hoàng | B30: 46236 | C30: KH03130 | D30: Vianca Vernice | E30: Wifi cầm tay | F30: 3850 | H30: 3850 | J30: 1785656644300
A31: Công ty | B31: 46236 | C31: KH01225 | D31: Đức Nguyễn Hữu | E31: Wifi cầm tay | F31: 3850 | H31: 3850 | J31: 1785118537589
A32: Công ty | B32: 46236 | C32: KH02493 | D32: Aboubacar Niakate | E32: Wifi cố định | F32: 2000 | H32: 2000 | I32: U00007811810 | J32: 1784860226637
A33: ĐLý Hoàng | B33: 46237 | C33: KH03213 | D33: imamura adora | E33: Wifi cầm tay | F33: 2800 | H33: 2800 | J33: 1785648913957
A34: Công ty | B34: 46237 | C34: KH02783 | D34: Roselyn Roque Navarro | E34: Wifi cầm tay | F34: 3850 | H34: 3850 | J34: 1785724690239
A35: ĐLý Việt | B35: 46237 | C35: KH03503 | D35: Taritz Matsuzaki | E35: Wifi cố định | F35: 500 | G35: 500 | I35: U00007892203 | J35: 1785559246581
A36: Công ty | B36: 46237 | C36: KH02612 | D36: エシオ チェリ | E36: Wifi cầm tay | F36: 2800 | H36: 2800 | J36: 1785658741422
A37: Công ty | B37: 46237 | C37: KH02883 | D37: Tadz Sndn | E37: Wifi cố định | F37: 2000 | H37: 2000 | I37: U00007819949 | J37: 1785207838734
A38: Công ty | B38: 46237 | C38: KH00794 | D38: Nguyễn Cường | E38: Wifi cầm tay | F38: 2800 | H38: 2800 | J38: 1785723345086
A39: Công ty | B39: 46237 | C39: KH00794 | D39: Nguyễn Cường | E39: Wifi cầm tay | F39: 1077 | H39: 1077 | J39: 1785723345086
A40: Công ty | B40: 46237 | C40: KH00794 | D40: Nguyễn Cường | E40: Wifi cầm tay | F40: 653 | H40: 653 | J40: 1785723345086
...

Sheet SBI
A1: ĐƠN VỊ | B1: NGÀY THÁNG | C1: NỘI DUNG | E1: MÃ KH | F1: TÊN KH | G1: LOẠI DỊCH VỤ | H1: THU | I1: CHI | J1: NOTE
H2: =SUBTOTAL(9,H3:H201) -> 6656563 | I2: =SUBTOTAL(9,I3:I201) -> 7228354 | N2: CHI | O2: THU
A3: Công ty | B3: =L3 -> 46237 | C3: =M3 -> 口座振替 シヤープフアイナンス | E3: CTY | F3: 3m intel | G3: Khác | H3: =O3 -> 0 | I3: =N3 -> 10890 | J3: Tiền thuê máy in | L3: 46237 | M3: 口座振替 シヤープフアイナンス | N3: 10890 | P3: 1528658 | Q3: -
A4: Công ty | B4: =L4 -> 46237 | C4: =M4 -> 振込＊チヤン テイ マイ チユオン | E4: CTY | F4: 3m intel | G4: Khác | H4: =O4 -> 0 | I4: =N4 -> 81880 | J4: Chuyển tiền vận chuyển cho kho | L4: 46237 | M4: 振込＊チヤン テイ マイ チユオン | N4: 81880 | P4: 1446778 | Q4: 経費精算
A5: Công ty | B5: =L5 -> 46237 | C5: =M5 -> 振込手数料 | E5: CTY | F5: 3m intel | G5: Khác | H5: =O5 -> 0 | I5: =N5 -> 140 | J5: Phí chuyển tiền | L5: 46237 | M5: 振込手数料 | N5: 140 | P5: 1446638 | Q5: -
A6: Công ty | B6: =L6 -> 46237 | C6: =M6 -> 振込＊クボ シヤロン エスプラゴサ | E6: CTY | F6: 3m intel | G6: Khác | H6: =O6 -> 0 | I6: =N6 -> 3000 | J6: Hoàn cọc | L6: 46237 | M6: 振込＊クボ シヤロン エスプラゴサ | N6: 3000 | P6: 1443638 | Q6: デポジット返金
A7: Công ty | B7: =L7 -> 46237 | C7: =M7 -> 振込手数料 | E7: CTY | F7: 3m intel | G7: Khác | H7: =O7 -> 0 | I7: =N7 -> 140 | J7: Phí chuyển tiền | L7: 46237 | M7: 振込手数料 | N7: 140 | P7: 1443498 | Q7: -
A8: Công ty | B8: =L8 -> 46237 | C8: =M8 -> 振込＊グエン ザー フオン | E8: CTY | F8: 3m intel | G8: Khác | H8: =O8 -> 0 | I8: =N8 -> 4000 | J8: Hoàn cọc | L8: 46237 | M8: 振込＊グエン ザー フオン | N8: 4000 | P8: 1439498 | Q8: デポジット返金
A9: Công ty | B9: =L9 -> 46237 | C9: =M9 -> 振込手数料 | E9: CTY | F9: 3m intel | G9: Khác | H9: =O9 -> 0 | I9: =N9 -> 140 | J9: Phí chuyển tiền | L9: 46237 | M9: 振込手数料 | N9: 140 | P9: 1439358 | Q9: -
A10: Công ty | B10: =L10 -> 46237 | C10: =M10 -> デビット ８３５１６２ | E10: CTY | F10: 3m intel | G10: Khác | H10: =O10 -> 0 | I10: =N10 -> 185 | J10: Cước vận chuyển | L10: 46237 | M10: デビット ８３５１６２ | N10: 185 | P10: 1439173 | Q10: -
A11: Công ty | B11: =L11 -> 46237 | C11: =M11 -> デビット ８３５７９０ | E11: CTY | F11: 3m intel | G11: Khác | H11: =O11 -> 0 | I11: =N11 -> 185 | J11: Cước vận chuyển | L11: 46237 | M11: デビット ８３５７９０ | N11: 185 | P11: 1438988 | Q11: -
A12: Công ty | B12: =L12 -> 46237 | C12: =M12 -> デビット ８４１５９８ | E12: CTY | F12: 3m intel | G12: Khác | H12: =O12 -> 0 | I12: =N12 -> 185 | J12: Cước vận chuyển | L12: 46237 | M12: デビット ８４１５９８ | N12: 185 | P12: 1438803 | Q12: -
A13: Công ty | B13: =L13 -> 46237 | C13: =M13 -> デビット ８４３７９２ | E13: CTY | F13: 3m intel | G13: Khác | H13: =O13 -> 0 | I13: =N13 -> 185 | J13: Cước vận chuyển | L13: 46237 | M13: デビット ８４３７９２ | N13: 185 | P13: 1438618 | Q13: -
A14: Công ty | B14: =L14 -> 46237 | C14: =M14 -> デビット ８４４３３４ | E14: CTY | F14: 3m intel | G14: Khác | H14: =O14 -> 0 | I14: =N14 -> 185 | J14: Cước vận chuyển | L14: 46237 | M14: デビット ８４４３３４ | N14: 185 | P14: 1438433 | Q14: -
... A27: Công ty | B27: =L27 -> 46238 | C27: =M27 -> デビット ０７８５７９ | E27: CTY | F27: 3m intel | G27: Khác | H27: =O27 -> 0 | I27: =N27 -> 185 | J27: Cước vận chuyển | L27: 46238 | M27: デビット ０７８５７９ | N27: 185 | P27: 1436028 | Q27: -
A28: Công ty | B28: =L28 -> 46239 | C28: =M28 -> デビット ３０９９８６ | E28: CTY | F28: 3m intel | G28: Khác | H28: =O28 -> 0 | I28: =N28 -> 185 | J28: Cước vận chuyển | L28: 46239 | M28: デビット ３０９９８６ | N28: 185 | P28: 1435843
A29: Công ty | B29: =L29 -> 46239 | C29: =M29 -> デビット ３３１９０９ | E29: CTY | F29: 3m intel | G29: Khác | H29: =O29 -> 0 | I29: =N29 -> 185 | J29: Cước vận chuyển | L29: 46239 | M29: デビット ３３１９０９ | N29: 185 | P29: 1435658
A30: Công ty | B30: =L30 -> 46239 | C30: =M30 -> デビット ３３２５９４ | E30: CTY | F30: 3m intel | G30: Khác | H30: =O30 -> 0 | I30: =N30 -> 185 | J30: Cước vận chuyển | L30: 46239 | M30: デビット ３３２５９４ | N30: 185 | P30: 1435473
A31: Công ty | B31: =L31 -> 46240 | C31: =M31 -> デビット ５８９４５６ | E31: CTY | F31: 3m intel | G31: Khác | H31: =O31 -> 0 | I31: =N31 -> 185 | J31: Cước vận chuyển | L31: 46240 | M31: デビット ５８９４５６ | N31: 185 | P31: 1435288
A32: Công ty | B32: =L32 -> 46240 | C32: =M32 -> デビット ５９０３５６ | E32: CTY | F32: 3m intel | G32: Khác | H32: =O32 -> 0 | I32: =N32 -> 185 | J32: Cước vận chuyển | L32: 46240 | M32: デビット ５９０３５６ | N32: 185 | P32: 1435103
A33: Công ty | B33: =L33 -> 46240 | C33: =M33 -> デビット ５９１０３３ | E33: CTY | F33: 3m intel | G33: Khác | H33: =O33 -> 0 | I33: =N33 -> 185 | J33: Cước vận chuyển | L33: 46240 | M33: デビット ５９１０３３ | N33: 185 | P33: 1434918
A34: Công ty | B34: =L34 -> 46240 | C34: =M34 -> デビット ６０９３０９ | E34: CTY | F34: 3m intel | G34: Khác | H34: =O34 -> 0 | I34: =N34 -> 185 | J34: Cước vận chuyển | L34: 46240 | M34: デビット ６０９３０９ | N34: 185 | P34: 1434733
A35: Công ty | B35: =L35 -> 46240 | C35: =M35 -> デビット ６２３２５２ | E35: CTY | F35: 3m intel | G35: Khác | H35: =O35 -> 0 | I35: =N35 -> 185 | J35: Cước vận chuyển | L35: 46240 | M35: デビット ６２３２５２ | N35: 185 | P35: 1434548
A36: Công ty | B36: =L36 -> 46240 | C36: =M36 -> デビット ６３２６００ | E36: CTY | F36: 3m intel | G36: Khác | H36: =O36 -> 0 | I36: =N36 -> 185 | J36: Cước vận chuyển | L36: 46240 | M36: デビット ６３２６００ | N36: 185 | P36: 1434363
A37: Công ty | B37: =L37 -> 46240 | C37: =M37 -> デビット ６３４１１１ | E37: CTY | F37: 3m intel | G37: Khác | H37: =O37 -> 0 | I37: =N37 -> 185 | J37: Cước vận chuyển | L37: 46240 | M37: デビット ６３４１１１ | N37: 185 | P37: 1434178
A38: Công ty | B38: =L38 -> 46240 | C38: =M38 -> デビット ６３６７０７ | E38: CTY | F38: 3m intel | G38: Khác | H38: =O38 -> 0 | I38: =N38 -> 185 | J38: Cước vận chuyển | L38: 46240 | M38: デビット ６３６７０７ | N38: 185 | P38: 1433993
A39: Công ty | B39: =L39 -> 46240 | C39: =M39 -> デビット ６３７２６１ | E39: CTY | F39: 3m intel | G39: Khác | H39: =O39 -> 0 | I39: =N39 -> 185 | J39: Cước vận chuyển | L39: 46240 | M39: デビット ６３７２６１ | N39: 185 | P39: 1433808
A40: Công ty | B40: =L40 -> 46240 | C40: =M40 -> 取消＊デビット ８６０９５９ | E40: CTY | F40: 3m intel | G40: Khác | H40: =O40 -> 185 | I40: =N40 -> 0 | J40: Cước vận chuyển | L40: 46240 | M40: 取消＊デビット ８６０９５９ | O40: 185 | P40: 1433993
A41: Công ty | B41: =L41 -> 46240 | C41: =M41 -> 振込＊テキ（カ | E41: TEKI | G41: Cầm tay | H41: =O41 -> 705651 | I41: =N41 -> 0 | J41: Công nợ tháng 7 Teki | L41: 46240 | M41: 振込＊テキ（カ | O41: 705651 | P41: 2139644
A42: Công ty | B42: =L42 -> 46241 | C42: =M42 -> 振込＊チヤン テイ マイ チユオン | E42: CTY | F42: 3m intel | G42: Khác | H42: =O42 -> 0 | I42: =N42 -> 93555 | J42: Chuyển tiền vận chuyển cho kho | L42: 46241 | M42: 振込＊チヤン テイ マイ チユオン | N42: 93555 | P42: 2046089
A43: Công ty | B43: =L43 -> 46241 | C43: =M43 -> 振込手数料 | E43: CTY | F43: 3m intel | G43: Khác | H43: =O43 -> 0 | I43: =N43 -> 140 | J43: Phí chuyển tiền | L43: 46241 | M43: 振込手数料 | N43: 140 | P43: 2045949
A44: Công ty | B44: =L44 -> 46241 | C44: =M44 -> デビット ８９２５６３ | E44: CTY | F44: 3m intel | G44: Khác | H44: =O44 -> 0 | I44: =N44 -> 185 | J44: Cước vận chuyển | L44: 46241 | M44: デビット ８９２５６３ | N44: 185 | P44: 2045764
A45: Công ty | B45: =L45 -> 46241 | C45: =M45 -> デビット ８９９２８３ | E45: CTY | F45: 3m intel | G45: Khác | H45: =O45 -> 0 | I45: =N45 -> 185 | J45: Cước vận chuyển | L45: 46241 | M45: デビット ８９９２８３ | N45: 185 | P45: 2045579
A46: Công ty | B46: =L46 -> 46241 | C46: =M46 -> デビット ９００１１２ | E46: CTY | F46: 3m intel | G46: Khác | H46: =O46 -> 0 | I46: =N46 -> 185 | J46: Cước vận chuyển | L46: 46241 | M46: デビット ９００１１２ | N46: 185 | P46: 2045394
A47: Công ty | B47: =L47 -> 46241 | C47: =M47 -> デビット ９４０２３０ | E47: CTY | F47: 3m intel | G47: Khác | H47: =O47 -> 0 | I47: =N47 -> 185 | J47: Cước vận chuyển | L47: 46241 | M47: デビット ９４０２３０ | N47: 185 | P47: 2045209
A48: Công ty | B48: =L48 -> 46241 | C48: =M48 -> デビット ９４１５３６ | E48: CTY | F48: 3m intel | G48: Khác | H48: =O48 -> 0 | I48: =N48 -> 185 | J48: Cước vận chuyển | L48: 46241 | M48: デビット ９４１５３６ | N48: 185 | P48: 2045024
A49: Công ty | B49: =L49 -> 46241 | C49: =M49 -> デビット ９４３４７３ | E49: CTY | F49: 3m intel | G49: Khác | H49: =O49 -> 0 | I49: =N49 -> 185 | J49: Cước vận chuyển | L49: 46241 | M49: デビット ９４３４７３ | N49: 185 | P49: 2044839
A50: Công ty | B50: =L50 -> 46241 | C50: =M50 -> デビット ９４４７２０ | E50: CTY | F50: 3m intel | G50: Khác | H50: =O50 -> 0 | I50: =N50 -> 185 | J50: Cước vận chuyển | L50: 46241 | M50: デビット ９４４７２０ | N50: 185 | P50: 2044654
A51: Công ty | B51: =L51 -> 46241 | C51: =M51 -> デビット ９４６０３７ | E51: CTY | F51: 3m intel | G51: Khác | H51: =O51 -> 0 | I51: =N51 -> 185 | J51: Cước vận chuyển | L51: 46241 | M51: デビット ９４６０３７ | N51: 185 | P51: 2044469
A52: Công ty | B52: =L52 -> 46241 | C52: =M52 -> デビット ９４７３４７ | E52: CTY | F52: 3m intel | G52: Khác | H52: =O52 -> 0 | I52: =N52 -> 185 | J52: Cước vận chuyển | L52: 46241 | M52: デビット ９４７３４７ | N52: 185 | P52: 2044284
...

Sheet Arai 7121
A1: NGÀY THÁNG | B1: THU | C1: CHI | E1: NỘI DUNG | G1: LOẠI DỊCH VỤ | H1: Mã U (NTT)
B2: =SUBTOTAL(9,B3:B1000) -> 973300 | C2: =SUBTOTAL(9,C3:C1000) -> 850000
A3: =I3 -> 20260801 | B3: =K3 -> 4000 | C3: =L3 -> 0 | D3: =M3 -> ことら | E3: =N3 -> ﾎｱﾝ ﾃｲ ﾎｱ | G3: Cố định | H3: U00007837117 | I3: 20260801 | J3: 202608010000001 | K3: 4000 | M3: ことら | N3: ﾎｱﾝ ﾃｲ ﾎｱ | O3: 301168
A4: =I4 -> 20260802 | B4: =K4 -> 4000 | C4: =L4 -> 0 | D4: =M4 -> 送金 | E4: =N4 -> ＲＡＪＡＰＡＫＳ | G4: Cố định | H4: U00007822655 | I4: 20260802 | J4: 202608020000001 | K4: 4000 | M4: 送金 | N4: ＲＡＪＡＰＡＫＳ | O4: 305168
A5: =I5 -> 20260803 | B5: =K5 -> 200000 | C5: =L5 -> 0 | D5: =M5 -> 振込 | E5: =N5 -> ｶ)ｼ-ｷﾔｽﾄ | G5: Khác | I5: 20260803 | J5: 202608030000001 | K5: 200000 | M5: 振込 | N5: ｶ)ｼ-ｷﾔｽﾄ | O5: 505168
A6: =I6 -> 20260804 | B6: =K6 -> 0 | C6: =L6 -> 200000 | D6: =M6 -> 通 帳 | E6: =N6 -> 0 | G6: Khác | I6: 20260804 | J6: 202608040000001 | L6: 200000 | M6: 通 帳 | O6: 305168
A7: =I7 -> 20260804 | B7: =K7 -> 1800 | C7: =L7 -> 0 | D7: =M7 -> 送金 | E7: =N7 -> ＮＧＵＹＥＮ Ｖ | G7: Cố định | H7: U00007825999 | I7: 20260804 | J7: 202608040000002 | K7: 1800 | M7: 送金 | N7: ＮＧＵＹＥＮ Ｖ | O7: 306968
A8: =I8 -> 20260805 | B8: =K8 -> 4000 | C8: =L8 -> 0 | D8: =M8 -> 送金 | E8: =N8 -> ＲＩＢＥＩＲＯ | G8: Cố định | H8: U00007819670 | I8: 20260805 | J8: 202608050000001 | K8: 4000 | M8: 送金 | N8: ＲＩＢＥＩＲＯ | O8: 310968
A9: =I9 -> 20260805 | B9: =K9 -> 2000 | C9: =L9 -> 0 | D9: =M9 -> 送金 | E9: =N9 -> ＴＡＫＥＩ ＣＯ | G9: Cố định | H9: U00007833901 | I9: 20260805 | J9: 202608050000002 | K9: 2000 | M9: 送金 | N9: ＴＡＫＥＩ ＣＯ | O9: 312968
A10: =I10 -> 20260806 | B10: =K10 -> 2000 | C10: =L10 -> 0 | D10: =M10 -> 送金 | E10: =N10 -> ＨＯＳＳＡＩＮ | G10: Cố định | H10: U00007829188 | I10: 20260806 | J10: 202608060000001 | K10: 2000 | M10: 送金 | N10: ＨＯＳＳＡＩＮ | O10: 314968
A11: =I11 -> 20260810 | B11: =K11 -> 4000 | C11: =L11 -> 0 | D11: =M11 -> 送金 | E11: =N11 -> ＭＵＮＡＭＢＡＭ | G11: Cố định | H11: U00007834092 | I11: 20260810 | J11: 202608100000001 | K11: 4000 | M11: 送金 | N11: ＭＵＮＡＭＢＡＭ | O11: 318968
A12: =I12 -> 20260823 | B12: =K12 -> 2000 | C12: =L12 -> 0 | D12: =M12 -> 送金 | E12: =N12 -> ＭＩＡ ＳＵＪＡ | G12: Cố định | H12: U00007836020 | I12: 20260823 | J12: 202608230000001 | K12: 2000 | M12: 送金 | N12: ＭＩＡ ＳＵＪＡ | O12: 320968
A13: =I13 -> 20260824 | B13: =K13 -> 2000 | C13: =L13 -> 0 | D13: =M13 -> 送金 | E13: =N13 -> ＮＥＰＡＬＩ Ｓ | G13: Cố định | H13: U00007766415 | I13: 20260824 | J13: 202608240000001 | K13: 2000 | M13: 送金 | N13: ＮＥＰＡＬＩ Ｓ | O13: 322968
A14: =I14 -> 20260824 | B14: =K14 -> 2000 | C14: =L14 -> 0 | D14: =M14 -> 送金 | E14: =N14 -> ＴＯＹＯＮＡＧＡ | G14: Cố định | H14: U00007842252 | I14: 20260824 | J14: 202608240000002 | K14: 2000 | M14: 送金 | N14: ＴＯＹＯＮＡＧＡ | O14: 324968
A15: =I15 -> 20260825 | B15: =K15 -> 1500 | C15: =L15 -> 0 | D15: =M15 -> 送金 | E15: =N15 -> ＴＯＹＯＤＡ Ｔ | G15: Cố định | H15: U00007833136 | I15: 20260825 | J15: 202608250000001 | K15: 1500 | M15: 送金 | N15: ＴＯＹＯＤＡ Ｔ | O15: 326468
A16: =I16 -> 20260826 | B16: =K16 -> 2000 | C16: =L16 -> 0 | D16: =M16 -> 送金 | E16: =N16 -> ＦＩＲＧＯ ＦＡ | G16: Cố định | H16: U00007821917 | I16: 20260826 | J16: 202608260000001 | K16: 2000 | M16: 送金 | N16: ＦＩＲＧＯ ＦＡ | O16: 328468
A17: =I17 -> 20260826 | B17: =K17 -> 500000 | C17: =L17 -> 0 | D17: =M17 -> 振込 | E17: =N17 -> ｶ)ｼ-ｷﾔｽﾄ | G17: Khác | I17: 20260826 | J17: 202608260000002 | K17: 500000 | M17: 振込 | N17: ｶ)ｼ-ｷﾔｽﾄ | O17: 828468
A18: =I18 -> 20260827 | B18: =K18 -> 0 | C18: =L18 -> 500000 | D18: =M18 -> 通 帳 | E18: =N18 -> 0 | G18: Khác | I18: 20260827 | J18: 202608270000001 | L18: 500000 | M18: 通 帳 | O18: 328468
A19: =I19 -> 20260827 | B19: =K19 -> 2000 | C19: =L19 -> 0 | D19: =M19 -> 送金 | E19: =N19 -> ＫＯＵＥＭＥＮＩ | G19: Cố định | H19: U00007874976 | I19: 20260827 | J19: 202608270000002 | K19: 2000 | M19: 送金 | N19: ＫＯＵＥＭＥＮＩ | O19: 330468
A20: =I20 -> 20260827 | B20: =K20 -> 4000 | C20: =L20 -> 0 | D20: =M20 -> 送金 | E20: =N20 -> ＰＨＡＮ ＴＨＩ | G20: Cố định | H20: U00007872512 | I20: 20260827 | J20: 202608270000003 | K20: 4000 | M20: 送金 | N20: ＰＨＡＮ ＴＨＩ | O20: 334468
A21: =I21 -> 20260827 | B21: =K21 -> 2000 | C21: =L21 -> 0 | D21: =M21 -> ことら | E21: =N21 -> ｸﾞｴﾝ ﾄﾞｳﾂｸ ﾄｳ | G21: Cố định | H21: U00007873626 | I21: 20260827 | J21: 202608270000004 | K21: 2000 | M21: ことら | N21: ｸﾞｴﾝ ﾄﾞｳﾂｸ ﾄｳ | O21: 336468
A22: =I22 -> 20260827 | B22: =K22 -> 2000 | C22: =L22 -> 0 | D22: =M22 -> 送金 | E22: =N22 -> ＶＵ ＭＡＮＨ | G22: Cố định | H22: U00007884054 | I22: 20260827 | J22: 202608270000005 | K22: 2000 | M22: 送金 | N22: ＶＵ ＭＡＮＨ | O22: 338468
A23: =I23 -> 20260827 | B23: =K23 -> 2000 | C23: =L23 -> 0 | D23: =M23 -> 送金 | E23: =N23 -> ＮＧＵＹＥＮ Ｖ | G23: Cố định | H23: U00007824109 | I23: 20260827 | J23: 202608270000006 | K23: 2000 | M23: 送金 | N23: ＮＧＵＹＥＮ Ｖ | O23: 340468
A24: =I24 -> 20260827 | B24: =K24 -> 3600 | C24: =L24 -> 0 | D24: =M24 -> 送金 | E24: =N24 -> ＮＧＵＹＥＮ Ｔ | G24: Cố định | H24: U00007850854 | I24: 20260827 | J24: 202608270000007 | K24: 3600 | M24: 送金 | N24: ＮＧＵＹＥＮ Ｔ | O24: 344068
A25: =I25 -> 20260828 | B25: =K25 -> 2000 | C25: =L25 -> 0 | D25: =M25 -> 送金 | E25: =N25 -> ＮＧＵＹＥＮ Ｈ | G25: Cố định | H25: U00007819941 | I25: 20260828 | J25: 202608280000001 | K25: 2000 | M25: 送金 | N25: ＮＧＵＹＥＮ Ｈ | O25: 346068 | P25: HD004318
A26: =I26 -> 20260828 | B26: =K26 -> 2000 | C26: =L26 -> 0 | D26: =M26 -> 振込 | E26: =N26 -> ｲｶﾞﾗｼｼﾞｴﾆﾌｱ- | G26: Cố định | H26: U00007835648 | I26: 20260828 | J26: 202608280000002 | K26: 2000 | M26: 振込 | N26: ｲｶﾞﾗｼｼﾞｴﾆﾌｱ- | O26: 348068
A27: =I27 -> 20260828 | B27: =K27 -> 2000 | C27: =L27 -> 0 | D27: =M27 -> 送金 | E27: =N27 -> ＳＹ ＴＨＩ Ｔ | G27: Cố định | H27: U00007839036 | I27: 20260828 | J27: 202608280000003 | K27: 2000 | M27: 送金 | N27: ＳＹ ＴＨＩ Ｔ | O27: 350068
A28: =I28 -> 20260828 | B28: =K28 -> 2000 | C28: =L28 -> 0 | D28: =M28 -> 送金 | E28: =N28 -> ｱﾗｲ ｷﾖｱｷ | G28: Cố định | H28: U00007835730 | I28: 20260828 | J28: 202608280000004 | K28: 2000 | M28: 送金 | N28: ｱﾗｲ ｷﾖｱｷ | O28: 352068
A29: =I29 -> 20260828 | B29: =K29 -> 2000 | C29: =L29 -> 0 | D29: =M29 -> 送金 | E29: =N29 -> ＮＧＵＹＥＮ Ｔ | G29: Cố định | H29: U00007805651 | I29: 20260828 | J29: 202608280000005 | K29: 2000 | M29: 送金 | N29: ＮＧＵＹＥＮ Ｔ | O29: 354068
A30: =I30 -> 20260828 | B30: =K30 -> 2000 | C30: =L30 -> 0 | D30: =M30 -> 送金 | E30: =N30 -> 大瀧 嘉賢 | G30: Cố định | H30: U00007861617 | I30: 20260828 | J30: 202608280000006 | K30: 2000 | M30: 送金 | N30: 大瀧 嘉賢 | O30: 356068
A31: =I31 -> 20260828 | B31: =K31 -> 2000 | C31: =L31 -> 0 | D31: =M31 -> 送金 | E31: =N31 -> ＳＵＹＡＬ ＧＡ | G31: Cố định | H31: U00007854447 | I31: 20260828 | J31: 202608280000007 | K31: 2000 | M31: 送金 | N31: ＳＵＹＡＬ ＧＡ | O31: 358068
A32: =I32 -> 20260828 | B32: =K32 -> 2000 | C32: =L32 -> 0 | D32: =M32 -> 送金 | E32: =N32 -> ＢＩＬＬＡＨ Ｍ | G32: Cố định | H32: U00007884015 | I32: 20260828 | J32: 202608280000008 | K32: 2000 | M32: 送金 | N32: ＢＩＬＬＡＨ Ｍ | O32: 360068
A33: =I33 -> 20260828 | B33: =K33 -> 2000 | C33: =L33 -> 0 | D33: =M33 -> 送金 | E33: =N33 -> ＴＡＫＡＨＡＳＨ | G33: Cố định | H33: U00007832610 | I33: 20260828 | J33: 202608280000009 | K33: 2000 | M33: 送金 | N33: ＴＡＫＡＨＡＳＨ | O33: 362068
A34: =I34 -> 20260828 | B34: =K34 -> 2000 | C34: =L34 -> 0 | D34: =M34 -> 送金 | E34: =N34 -> ＢＡＵＴＩＳＴＡ | G34: Cố định | H34: U00007807764 | I34: 20260828 | J34: 202608280000010 | K34: 2000 | M34: 送金 | N34: ＢＡＵＴＩＳＴＡ | O34: 364068
A35: =I35 -> 20260828 | B35: =K35 -> 2000 | C35: =L35 -> 0 | D35: =M35 -> 送金 | E35: =N35 -> ＶＵ ＴＵＮＧ | G35: Cố định | H35: U00007828034 | I35: 20260828 | J35: 202608280000011 | K35: 2000 | M35: 送金 | N35: ＶＵ ＴＵＮＧ | O35: 366068
A36: =I36 -> 20260828 | B36: =K36 -> 2000 | C36: =L36 -> 0 | D36: =M36 -> 送金 | E36: =N36 -> ＩＲＶＡＮ ＰＥ | G36: Cố định | H36: U00007777463 | I36: 20260828 | J36: 202608280000012 | K36: 2000 | M36: 送金 | N36: ＩＲＶＡＮ ＰＥ | O36: 368068
A37: =I37 -> 20260828 | B37: =K37 -> 2000 | C37: =L37 -> 0 | D37: =M37 -> 送金 | E37: =N37 -> 佐藤 由香里 | G37: Cố định | H37: U00007842185 | I37: 20260828 | J37: 202608280000013 | K37: 2000 | M37: 送金 | N37: 佐藤 由香里 | O37: 370068
... A47: =I47 -> 20260831 | B47: =K47 -> 2000 | C47: =L47 -> 0 | D47: =M47 -> 送金 | E47: =N47 -> ＳＡＮＴＯＳ Ｒ | G47: Cố định | H47: U00007787781 | I47: 20260831 | J47: 202608310000003 | K47: 2000 | M47: 送金 | N47: ＳＡＮＴＯＳ Ｒ | O47: 391068
A48: =I48 -> 20260831 | B48: =K48 -> 150000 | C48: =L48 -> 0 | D48: =M48 -> 振込 | E48: =N48 -> ｶ)ｼ-ｷﾔｽﾄ | G48: Khác | I48: 20260831 | J48: 202608310000004 | K48: 150000 | M48: 振込 | N48: ｶ)ｼ-ｷﾔｽﾄ | O48: 541068
A49: =I49 -> 20260831 | B49: =K49 -> 4000 | C49: =L49 -> 0 | D49: =M49 -> 送金 | E49: =N49 -> ＨＡＳＥＥＢ Ｍ | G49: Cố định | H49: U00007845671 | I49: 20260831 | J49: 202608310000005 | K49: 4000 | M49: 送金 | N49: ＨＡＳＥＥＢ Ｍ | O49: 545068
...
